Workbook

Sheet 他部署受付 - 作業内容管理・進捗
B1: システム運営課 - 作業内容管理・進捗
A3: f | B3: No. | C3: 依頼日 | D3: 依頼部署 | E3: 課題件名 | F3: 課題内容 | G3: 対応内容 | H3: 期限 | I3: 状況 | J3: 備考 | K3: 進捗 | L3: 効果 | M3: 対応者 | N3: 年度
B4: =ROW()-3 -> 1 | C4: 45506 | D4: 商品部 商品管理課 | E4: 楽天カテゴリの取得 | F4: データシートの「楽天商品カテゴリ」が非常に細かく分類されており、特定の商品がどのカテゴリに当てはまるのかを判断するのが非常に困難で時間がかかっています。 | G4: WEBスクレイピングを利用して 既に商品が存在するなら他社で一番使われているカテゴリを取得することで作業の効率化とデータの正確性向上を目指す。 また同時にYahooカテゴリについても取得できるようにしました。 | H4: 45520 | I4: 完了 | K4: 現在はメーカーからのデータシートにカテゴリが入っているものが多く、プログラムはあまり使用されていない状況とのこと。
B5: =ROW()-3 -> 2 | C5: 45527 | D5: マーケティング部 サイト運営課 | E5: b-dash用のデータ作成 週次作業 | F5: 基幹データを抽出してb-dash(販促メール)用に加工する作業が、単純だがファイルサイズが大きいため時間がかかっています。 | G5: 基幹データを抽出する際に、余計なデータを削除し、b-dash用にデータを整える作業を、データファイルを開かずにスムーズに処理・保存できるプログラムを作成しました。 この取り組みにより、作業の効率が向上し、時間の短縮を実現しました。 | H5: 45534 | I5: 完了 | K5: 削減工数：約３時間/月 また、上記の時間削減だけでなく、 Excel上の手処理によるミスを防止できることも大きなメリットとなっているとのこと。
B6: =ROW()-3 -> 3 | C6: 45527 | D6: マーケティング部 サイト運営課 | E6: b-dash用のデータ作成 月次作業 | F6: 基幹データ(直近25か月分)を抽出してb-dash(販促メール)用に取得する行程に時間がかかっています。 | G6: プログラムを作成しデータを自動取得し、利用したい時にデータが準備してある状態にすることで作業効率を高めました。 | H6: 45568 | I6: 完了 | K6: 削減工数：不明
B7: =ROW()-3 -> 4 | C7: 45540 | D7: 商品部 商品管理課 | E7: 短縮商品名の取得 | F7: 商品データシートでは、データベースや納品書印字の制約により、限られた文字数で商品を表現する必要がありました。このため、適切な表現を考え入力する作業が、非常に手間と時間のかかるプロセスとなっていました。この問題は業務全体の効率に影響を及ぼし、現場の負担を大幅に増加させていました。 | G7: ChatGPTのAPIを使って自動で商品名を提案する機能を導入することで手作業が減り、作業時間が短縮されます。結果として、データ入力が効率化され、スタッフの負担が軽くなります。 | I7: 完了 | K7: とりらえず完了！
B8: =ROW()-3 -> 5 | C8: 45547 | D8: 事業管理部 | E8: SQLの作成 受注データ取得用 | F8: DWH用の受注データを作成する工程で、現在は基幹のインプロで複数取得したデータを組わせてデータを作成しているので、作成に時間がかかってしまっている。 | G8: 一度でデータを作成できるようにインプロからSQLに作り直し、直接CSVファイルとして書き出すことで作業負担を減らします。 | I8: 完了 | K8: ベースのSQLは作成済み。 岡村部長と随時チューニング中です。
B9: =ROW()-3 -> 6 | C9: 45555 | D9: 商品部 商品管理課 | E9: 売価データの統合 | F9: 売価データ、契約単価の更新に伴い、大量のエクセルファイル(毎月およそ250ファイル)を1つにまとめる作業が発生していました。この作業は現在すべて手作業で行われており、作業に時間がかかっていました。 | G9: プログラムを作成し、この作業を完全自動化しました。 これによりこれまで数時間を費やしていた作業がわずか数秒で完了するようになりました。 | H9: 45555 | I9: 完了 | K9: 削減工数：約3時間→約4分 作業時間の98.8%削減。
B10: =ROW()-3 -> 7 | C10: 45567 | D10: マーケティング部 サイト運営課 | E10: プライスサーチの自社ツール化 | F10: 楽天とヤフーでの価格調査に利用していた「プライスサーチ」が、2024年9月から調査可能な件数に制限(8日間内で7.5万点まで)がかかり、価格調査にかかる日数が2倍になり、調査件数も半減しました。このためリアルタイムの価格を取得できず、他店の価格追跡や価格調整の精度が低下しています。 現在は9.8万円/月(税抜) 現在は価格調査する商品を厳選して対応中。 | G10: 自社で価格を調査するプログラムを開発し、商品価格データを収集します。 | H10: 2025/7末 | I10: 完了 | K10: 楽天約55万件、ヤフー約53万件の価格調査データを1日で取得し、自動的にNASサーバーに保存できるツールを実装。 楽天は稼働開始から2か月、ヤフーは１か月が経過しましたが、現在までに大きな問題は発生していません。 今後も取得データの確認は継続しますが、ツールとしての実装は完了としています。
B11: =ROW()-3 -> 8 | C11: 45573 | D11: 顧客部サービス課 | E11: インプロ出力ファイルの破損 | F11: インプロで出力したエクセルファイルが開けるときと開けない場合がある。開けない場合はやり直さないといけないので無駄な作業になっている。 | G11: プログラムを作成し、別ルートで同じ結果のファイルを出力するようにしました。 | H11: 45573 | I11: 完了 | K11: 根本的な解決にはなっていないので、引き続き調査してみます。
B12: =ROW()-3 -> 9 | C12: 45594 | D12: 顧客部 顧客課 | E12: 買い物コネクトの欠品対応ツールの自動化 | F12: 買い物コネクトにおける現在の業務を簡略化したい。 【現在の流れ】 ・インプロで買い物コネクトの欠品情報を取得しそれをエクセル化 →手動で注文日ごと、施設ごとに並び替え →表示されている伝票番号をSCAWの受注画面で一つ一つ入力し、 欠品している商品の入荷日を調べ、お客様へ案内する | G12: エクセルで全ての情報を一括で取得できるようにしました。 | H12: 45597 | I12: 完了 | K12: データの作成に３０分かかっていたのが約１０秒で完了できるようになりました。 作業時間は 約99.44% 削減。
B13: =ROW()-3 -> 10 | C13: 45597 | D13: 顧客部 サービス課 | E13: 基幹⇔OA間のデータ移動 | F13: 研修を通じ基幹とOA間でのデータの移行作業に時間が取られていると感じました。 | G13: 基幹ネットワークとOAネットワークを行き来できる端末を作成し、 フォルダを監視し、そのフォルダに入ったものを移動するプログラムを作成することにより、基幹⇔OA間のデータ移行をスムーズにできるようになります。 セキュリティの為、該当の端末とOA側にはウィルス対策をし、ユーザーは限定し、移動ファイルのログは残すようにします。 | H13: ー | I13: 完了 | K13: 同時接続数の問題で中継端末を端末→サーバーに変更。 現在テスト運用中。 問題なければ２月に正式運用したい。 ※USB端末管理台帳をどうするか
B14: =ROW()-3 -> 11 | C14: 45618 | D14: 顧客部 サービス課 | E14: 買い物コネクト 伝票の対象化と出荷指示解除のツール化 | F14: 買い物コネクトの伝票の対象化と出荷指示解除の作業が平日毎日あり、 確認することも多く通常のObjectBrowserを使った方法だと厳しい。 | G14: 福岡システムにツール化してもらいました。 | H14: ー | I14: 完了 | K14: ツールの運用を顧客部に譲渡済み。
B15: =ROW()-3 -> 12 | C15: 45617 | D15: 営業部 | E15: BtoBの価格調査 | F15: アスクル、たのめーる、カウネット、モノタロウなど 営業で他社サイトの商品をForestで買ったらいくらになるかの調査に 現在のところ、マンパワーで作業していてかなり時間がかかっているので 改善できるなら改善したい、とのこと。 | G15: 楽天やヤフーのプライスサーチのロジックを使って、BtoBのサイトから欲しい情報を抽出します。 | I15: 完了 | K15: まずはアスクルのデータ取得を行い、42,000件の調査が完了しました。 人の手で1行の調査に約30秒かかるところが1秒で終わりました。 作業時間は 約96.67% 削減。 いったん完了。
B16: =ROW()-3 -> 13 | C16: 45617 | D16: 物流部 | E16: 倉庫レイアウトの データ作成自動化 | F16: 現在、毎朝インプロでデータを抽出してそれをCSVに変換(約３０分前後)し、そのデータをもとに倉庫レイアウト修正作業をしている。 自動化が実現できると業務がスムーズになるので対応をお願いしたい、とのこと。 | G16: インプロと同じ結果になるSQLを作成しsqlplusのスプール機能を使って 直接CSVに出力し、それをバッチファイルにしてスケジューリングすることで 自動化が実現できると考えます。 | H16: 45628 | I16: 完了 | K16: ツール（インプロ）が７個あり、全部対応完了。 今までのインプロでの作業でもデータ取得まで待機しているわけではなく、他の作業を並行して行っていたため、効率の向上を数値で表現するのは難しいですが、自動化により、作業を開始する前にデータがすでに準備されている状態になり、全体の流れがスムーズになりました、とのこと。
B17: =ROW()-3 -> 14 | C17: 45621 | D17: 物流部 川口配送センター | E17: コピー用紙配送の 一般貨物管理表の作成 | F17: 新しい一般貨物配送業務「コピー用紙配送」ができたが、 荷主と下請けの請求金額を精査する管理表が欲しい。 | G17: 適切なエクセルの計算式を入力するだけです。 | H17: 45629 | I17: 完了 | K17: 荷主への請求額、 各業者への支払額が一目でわかるようにしました。
B18: =ROW()-3 -> 15 | C18: 45625 | D18: マーケティング部 サイト運営課 | E18: 楽天の商品更新csv | F18: イベント期間中に全商品に対し商品名を更新しているが、 商品数が多い（約50万点強）ため元となるexcelを作成し、1つのcsvに対し商品数5万点までのため、そこから計11個のcsvへ手作業で分けているので作業を簡略化したい。 | G18: プログラムで自動化します。 | H18: 45630 | I18: 完了 | K18: 手作業だと１０分？かかっていたのが約15秒で終わるようになりました。 作業時間は約 97.5% 削減。
B19: =ROW()-3 -> 16 | C19: 45625 | D19: マーケティング部 サイト運営課 | E19: EDION連携納期回答【花王】の 応答速度の改善 | F19: SCAWメニューの「EDION連携納期回答【花王】」の 応答速度が15:30ぐらいから開始しても17:30以降になるぐらい遅い。 また動作中はSCAW業務が行えない。 （現在はリモートで１台SCAW端末を利用して対応しているとのこと） | G19: メニューでどのSQLが呼ばれているか調査して、 必要であればSQLを改修してみます。 また他の方法でデータを取得することができればSCAW業務は行えるので、合わせて調査してみます。 | H19: ー | I19: 完了 | K19: 下村さんにシステム内で使われているSQLの見直しを して修正していただきました。 今まで1時間かかっていたところが、2秒程度で終わるようになったそうです。 1時間が2秒で終わる削減効果は99.94%になります。
B20: =ROW()-3 -> 17 | C20: 45627 | D20: 商品部 商品一課 | E20: 未引き当てメールの題名変更 | F20: 理由は各MDが自分の担当の商品が欠品していることを確認するために、欠品のメールの題名に大分類コードを入れられるか、確認してほしい。 | G20: 簡単にできるか、福岡に確認。 | H20: ー | I20: 完了 | K20: 簡単にはできないそう。 福岡対応予定。 2/13 完了
B21: =ROW()-3 -> 18 | C21: 45631 | D21: 商品部 商品二課 | E21: 売価の設定方法について | F21: セールなどで期間限定で売価を変更するが、変更中に他の売価を変更すると 元の売価がわからなくなってしまう。 | G21: 現在の運用を調査して、対応。 | H21: ー | I21: 完了 | K21: 福岡システムで対応予定。
B22: =ROW()-3 -> 19 | C22: 45638 | D22: 商品部 商品一課 | E22: MDの日時作業 | F22: MDが毎日自分の担当商品の前日の売上データを、岡村さんが作成してくれたLookerStudioから取得してエクセルに入力している。10分ぐらいで終わるが、毎日の作業なので簡略化出来るならやってほしい。 | G22: SCAWデータを使って作成しているので、簡単に取れないか調査してみる。 | H22: ー | I22: 完了 | K22: データを見る
B23: =ROW()-3 -> 20 | C23: 45638 | D23: 管理部 管理課 | E23: 値引伝票自動作成 | F23: 値引伝票を作成するためのデータ作成業務で 月に約３時間ほどの工数で手動で作業しているものを、 ミスもあるので自動作成するようにしてほしい。 | G23: 今までSQLで抽出したデータを加工していたものをSQL内で自動計算して結果を出力することで工数を減らせないか検討中です。 | H23: ー | I23: 完了 | K23: 完了済み。 しばらくは今までの作業でやっていただき、 ツールと比べて整合性のチェックをしてもらっています。
B24: =ROW()-3 -> 21 | C24: 45639 | D24: 顧客部 顧客課 | E24: 重要メモ抽出ツールの改修 | F24: 重要メモ抽出ツールで、お客様から問い合わせがあった際に色々調べなくて済むように、表示内容を追加したい。 | G24: インプロを修正します。 | H24: ー | I24: 完了 | K24: 完了済み。 30分/日ぐらい短縮できているとのこと。
B25: =ROW()-3 -> 22 | C25: 45645 | D25: 商品部 商品一課 | E25: 楽天の価格調査 | F25: 各MDが自分の商材リストの最新の楽天価格を調査する際、 WEBを回覧すると時間がかかるのでツール化してほしい。 | G25: マーケティング部で使う予定のプライスサーチをカスタマイズしてＭＤさんが使いやすいように改良します。 | H25: ー | I25: 完了 | K25: 完了済み。 箱バラ等が取れるように別途チューニング中。
B26: =ROW()-3 -> 23 | C26: 45646 | D26: マーケティング部 販売促進課 | E26: b→dashのSFTP自動連携 | F26: 「新規入会後から７日経ったお客様にクーポンメールを送信する」等を自動でやりたいが、現状できていない。 B-dashのデータ自動登録機能をうまく利用して販促に繋げたい。 | G26: SFTPでB-Dashのサーバーにアップロードすると自動的に登録できる機能があるので、それとNASの基幹→OAへのデータ移動をうまく連携させて自動化できるようにする。 | H26: 2025/2末 | I26: 完了 | K26: 希望は２月末まで。 自動アップロード作成＋テスト済み。 1/23(木)の朝に本番。
B27: =ROW()-3 -> 24 | C27: 45652 | D27: システム部 | E27: Google Play Console デベロッパー アカウント | F27: 配送支援アプリをGoogle Playにあげているが、 デベロッパーアカウントの設定が必要になっており、対応しないと「デベロッパープロフィールとアプリが削除される」と注意表示されている。 | G27: 調査中 | H27: 45756 | I27: 完了 | K27: 調査中です。
B28: =ROW()-3 -> 25 | C28: 45663 | D28: システム部 | E28: 基幹メールアドレスの枯渇 | F28: 現在基幹メールアドレスが枯渇していて、新規で作れない状態になっている。 | G28: メールサーバーのソフトウェアを入れ替えて対応。 | H28: 2025/2末 | I28: 完了 | K28: ※古いメールはサーバー上から削除されます。 PCで受信したメールはそのまま残ります。 長期間使っていないメールは受信しておいてください。 移行する日程が決まりましたらまたご連絡します。
B29: =ROW()-3 -> 26 | C29: 45672 | D29: 商品管理課 | E29: アスクルデータ情報の取得 | F29: 現在アスクルデータの取得をオクトパスという無料ソフトを使って取得しているが、１度に２万件、月に５万件の制限がある。 有料版なら無制限 ＄９９/月 | G29: 自社で作成することで、 無制限で同じデータを取得可能。 | H29: 45691 | I29: 完了 | K29: 作成済み。 4万件のデータ取得で問題なく完了。
B30: =ROW()-3 -> 27 | C30: 45677 | D30: 商品管理課 | E30: カタログの文字校正 | F30: カタログの規約(PDF)が、規約文書(Word)と差異がないか調査してもらいたい。 | G30: PDFとWordをテキスト化して、プログラムで精査する。 | H30: 45680 | I30: 完了 | K30: 完了済み。
B31: =ROW()-3 -> 28 | C31: 45691 | D31: 商品部 商品一課 | E31: 楽天の価格調査（箱バラ） | F31: 以前に作った楽天の価格調査だとJANコードで商品を検索して価格を取得するが、たとえば「６本入り」のデータがとれない。 | G31: 再検索機能を追加して、売価に対して明らかに おかしい結果のものは商品名と価格を絞って検索して目的の情報を取れるようにする。 | H31: - | I31: 完了 | K31: 2/15完了。
B32: =ROW()-3 -> 29 | C32: 45693 | D32: 商品部 商品一課 | E32: カウネットの売価データ取得 | F32: カウネットの価格調査を自動化したい | G32: 自動化プログラムを開発し、商品価格データを収集します。 | H32: - | I32: 完了 | K32: 完了済み。
B33: =ROW()-3 -> 30 | C33: 45693 | D33: マーケティング部 販売促進課 | E33: b→dashのSFTP自動連携 (伝票データ) | F33: 伝票データも顧客データと同じように自動連係したい | G33: B-Dashへのアップロードするプログラムは汎用性を持たせているので顧客データと同じように伝票データ作成プログラムを作成して対応します。 | H33: 45696 | I33: 完了 | K33: 2/19完了。
B34: =ROW()-3 -> 31 | C34: 45694 | D34: 物流部 川口配送センター | E34: 請求書確認の修正 | F34: コピー機配送請求書の精査で、「コース」も見るようにしたい。 | G34: ピボットテーブルの項目を追加します。 | H34: - | I34: 完了 | K34: 完了済み。
B35: =ROW()-3 -> 32 | C35: 45693 | D35: 商品管理課 | E35: アスクルPB品のデータ取得 | F35: アスクルのPB品にしぼった情報取得がしたい。 | G35: 巡回プログラムを作成して情報を取得します。 | I35: 完了 | K35: No39で対応します。
B36: =ROW()-3 -> 33 | C36: 45700 | D36: 商品部 | E36: カインズホームの情報取得 | F36: 当社の扱いにないが多くのお客様が欲しいと思う 商品(塊＝群)を探し出して品揃え強化を図りたいので カインズホームの商品情報を取得したい。 | G36: プログラムを作成して自動取得します。 | H36: 45703 | I36: 完了 | K36: 2/13に完了済み。
B37: =ROW()-3 -> 34 | C37: 45702 | D37: 商品部 | E37: DCMの情報取得 | F37: カインズホームのデータだとJAN情報がないものが多く 自社と付け合わせが難しいのでDCMの情報で取得して欲しい。 | G37: プログラムを作成して自動取得します。 | H37: 45703 | I37: 完了 | K37: 2/14に完了済み。
B38: =ROW()-3 -> 35 | C38: 45707 | D38: 商品部 | E38: カウネットの情報取得 | F38: DCMと同じように「たのめーる」での全データ情報が欲しい。 | G38: プログラムを作成して自動取得します。 | H38: - | I38: 完了 | K38: 一応今は不要とのことでとりあえず完了にしてます。 必要になったら再申請してください。
B39: =ROW()-3 -> 36 | C39: 45707 | D39: 商品部 | E39: たのめーるの情報取得 | F39: DCMと同じように「たのめーる」での全データ情報が欲しい。 | G39: プログラムを作成して自動取得します。 | H39: - | I39: 完了 | K39: No.51で完了済み。
B40: =ROW()-3 -> 37 | C40: 45707 | D40: 商品部 | E40: アスクルの情報取得 | F40: DCMと同じようにカウネットでの全データ情報が欲しい。 | G40: プログラムを作成して自動取得します。 | I40: 完了 | K40: No39で対応。
B41: =ROW()-3 -> 38 | C41: 45708 | D41: 営業部 | E41: アスクルの申込番号に対する 自社商品データ取得 | F41: 営業で利用したいので、エクセルにあるアスクルの申込番号の現在価格とフォーレストの価格を調査してほしい。 | G41: プログラムを作成して自動取得します。 | I41: 完了 | K41: 2/21に完了済み。
...

Sheet ヘルプデスク - 作業内容管理・進捗
D1: システム運営課 ヘルプデスク - 作業内容管理・進捗
B2: No1 | C2: 202606 | D2: 支援 | E2: 伊藤 | F2: 46199.381 | G2: 46199.392 | M2: 佐々嶌さん | N2: 低 | O2: 完了 | P2: DocuWorksのインストールフォルダの場所の共有 | Q2: チャットにて共有を実施。
B3: No2 | C3: 202606 | D3: 支援 | E3: 伊藤 | F3: 46199.441 | G3: 46199.451 | H3: 対応日数(営業日) | I3: 実作業時間 | J3: ジャンル | K3: 依頼部署 | L3: 依頼部署(課) | M3: 宮澤直也様 | N3: 低 | O3: 完了 | P3: 注文書の送付および、配送先の「福岡開発室」への変更依頼 | Q3: メールにて送付と変更依頼を実施。
B4: No3 | C4: 202606 | D4: 支援 | E4: 伊藤 | F4: 46199.448 | G4: 46199.458 | H4: =IF(F4="", "", NETWORKDAYS.INTL(F4, G4, 11,祝日シート!A:A)) -> 1 | I4: 0.16666667 | J4: OA端末関連 | K4: 商品部 | M4: 坂田部長 | N4: 低 | O4: 完了 | P4: UPSバッテリー購入の手配 | Q4: 稟議通過を報告し、Amazonでの購入手配をチャットで依頼。
B5: No4 | C5: 202606 | D5: 支援 | E5: 伊藤 | F5: 46199.478 | G5: 46199.489 | H5: =IF(F5="", "", NETWORKDAYS.INTL(F5, G5, 11,祝日シート!A:A)) -> 1 | I5: 0.083333333 | J5: OA端末関連 | K5: システム部 | M5: 篠嵜様 | N5: 低 | O5: 完了 | P5: スマホ機種変更（2回線）の正式発注と納期確認、ガラホの見積もり確認 | Q5: メールにて発注および確認を実施。
B6: No5 | C6: 202606 | D6: 支援 | E6: 伊藤 | F6: 46202.451 | G6: 46202.462 | H6: =IF(F6="", "", NETWORKDAYS.INTL(F6, G6, 11,祝日シート!A:A)) -> 1 | I6: 0.041666667 | J6: OA端末関連 | K6: システム部 | M6: 髙山さん | N6: 低 | O6: 完了 | P6: 足達さんのアカウント連携トラブル対応 | Q6: デバイス削除と再サインインの手順をチャットで指示。
B7: No6 | C7: 202606 | D7: 支援 | E7: 伊藤 | F7: 46202.547 | G7: 46202.558 | H7: =IF(F7="", "", NETWORKDAYS.INTL(F7, G7, 11,祝日シート!A:A)) -> 1 | I7: 0.020833333 | J7: OA端末関連 | K7: マーケティング部 | M7: 野崎さん | N7: 低 | O7: 完了 | P7: Windows 11環境での基幹端末操作（カーソルずれ）の解消 | Q7: 解消のための設定手順をチャットで伝授し、解決に導く。
B8: No7 | C8: 202606 | D8: 支援 | E8: 伊藤 | F8: 46202.554 | G8: 46202.565 | H8: =IF(F8="", "", NETWORKDAYS.INTL(F8, G8, 11,祝日シート!A:A)) -> 1 | I8: 0.010416667 | J8: 総務関連 | K8: 管理部 | M8: 坂田部長 | N8: 低 | O8: 完了 | P8: 北澤さんの携帯番号重複への対応方針の確認 | Q8: 新規購入とするか交換とするかの判断を仰ぐため、チャットで相談。
B9: No8 | C9: 202606 | D9: 支援 | E9: 伊藤 | F9: 46202.603 | G9: 46202.614 | H9: =IF(F9="", "", NETWORKDAYS.INTL(F9, G9, 11,祝日シート!A:A)) -> 1 | I9: 0.013888889 | J9: 基幹端末関連 | K9: 商品部 | M9: 磯辺さん | N9: 低 | O9: 完了 | P9: 福岡へのガラケー発送対応 | Q9: 発送が完了した旨をチャットで報告。
B10: No9 | C10: 202606 | D10: 支援 | E10: 伊藤 | F10: 46202.607 | G10: 46202.617 | H10: =IF(F10="", "", NETWORKDAYS.INTL(F10, G10, 11,祝日シート!A:A)) -> 1 | I10: 0.010416667 | J10: 基幹端末関連 | K10: マーケティング部 | M10: 佐々嶌さん | N10: 低 | O10: 完了 | P10: PythonのExcelツールエラーに関する野崎さんからの問い合わせ対応 | Q10: エラーの内容を佐々嶌さんへチャットで転送し、状況を共有。
B11: No10 | C11: 202606 | D11: 支援 | E11: 伊藤 | F11: 46202.667 | G11: 46202.678 | H11: =IF(F11="", "", NETWORKDAYS.INTL(F11, G11, 11,祝日シート!A:A)) -> 1 | I11: 0.010416667 | J11: 基幹端末関連 | K11: 商品部 | M11: 下村部長 | N11: 低 | O11: 完了 | P11: 自身の有給取得と通院によるシフト変更届の提出 | Q11: チャットにて連絡・提出。
B12: No11 | C12: 202606 | D12: 支援 | E12: 伊藤 | F12: 46203.349 | G12: 46203.359 | H12: =IF(F12="", "", NETWORKDAYS.INTL(F12, G12, 11,祝日シート!A:A)) -> 1 | I12: 0.20833333 | J12: OA端末関連 | K12: マーケティング部 | M12: 出嶋様 | N12: 低 | O12: 完了 | P12: 購入機器の配送先（大宮本社）および領収書宛名等の情報回答 | Q12: メールにて必要な情報を回答。
B13: No12 | C13: 202606 | D13: 支援 | E13: 伊藤 | F13: 46203.366 | G13: 46203.376 | H13: =IF(F13="", "", NETWORKDAYS.INTL(F13, G13, 11,祝日シート!A:A)) -> 1 | I13: 0.27083333 | J13: ネットワーク | K13: システム部 | M13: 中居様 | N13: 低 | O13: 完了 | P13: Office 2019のKMSホストキーに関する問い合わせ | Q13: メールにて技術的な問い合わせを実施。
B14: No13 | C14: 202606 | D14: 支援 | E14: 伊藤 | F14: 46203.606 | G14: 46203.616 | H14: =IF(F14="", "", NETWORKDAYS.INTL(F14, G14, 11,祝日シート!A:A)) -> 1 | I14: 0.125 | J14: 総務関連 | K14: 商品部 | M14: 髙山さん | N14: 低 | O14: 完了 | P14: 足達さんのスマホ設定エラー対応 | Q14: 設定が上手くいかないため、端末を預かってこちらで再設定する旨をチャットで連絡。
B15: No14 | C15: 202607 | D15: 支援 | E15: 伊藤 | F15: 46204.409 | G15: 46204.419 | H15: =IF(F15="", "", NETWORKDAYS.INTL(F15, G15, 11,祝日シート!A:A)) -> 1 | I15: 0.041666667 | J15: OA端末関連 | K15: システム部 | M15: 石鍋さん | N15: 低 | O15: 完了 | P15: 貯蔵品（PC・ディスプレイ）の数量確認と報告 | Q15: チャットにて現在の在庫数量を報告。
... B22: No21 | C22: 202607 | D22: 支援 | E22: 伊藤 | F22: 46216.495 | G22: 46216.506 | H22: =IF(F22="", "", NETWORKDAYS.INTL(F22, G22, 11,祝日シート!A:A)) -> 1 | I22: 0.0625 | J22: SCAW関連 | K22: 営業管理部 | M22: 坂田部長 | N22: 低 | O22: 完了 | P22: 派遣社員用端末のOffice365ライセンス追加依頼 | Q22: 坂田部長へチャットで追加手配を依頼。
B23: ="No"&ROW()-3 -> No20 | C23: =IFERROR(IF(G23<>"",TEXT(G23,"yyyymm"),""),"") -> 202408 | D23: 運用 | E23: 伊藤 | F23: 45522.667 | G23: 45522.688 | H23: =IF(F23="", "", NETWORKDAYS.INTL(F23, G23, 11,祝日シート!A:A)) -> 0 | I23: 0.020833333 | J23: 総務関連 | K23: 商品部 | M23: 小幡 | N23: 低 | O23: 完了 | P23: 小幡用ノートPCのキッティング作業 田中・加藤 商品管理部 Scawメニュー付与 | Q23: 左記の内容で実施。
B24: ="No"&ROW()-3 -> No21 | C24: =IFERROR(IF(G24<>"",TEXT(G24,"yyyymm"),""),"") -> 202408 | D24: 運用 | E24: 伊藤 | F24: 45529.375 | G24: 45529.708 | H24: =IF(F24="", "", NETWORKDAYS.INTL(F24, G24, 11,祝日シート!A:A)) -> 0 | I24: 0.33333333 | J24: 総務関連 | K24: マーケティング部 | M24: 山本 | N24: 低 | O24: 完了 | P24: 山本ノートPCキッティング（作業用スクリプト制作含む） | Q24: 左記の内容で実施。
B25: ="No"&ROW()-3 -> No22 | C25: =IFERROR(IF(G25<>"",TEXT(G25,"yyyymm"),""),"") -> 202408 | D25: 障害 | E25: 伊藤 | F25: 45529.458 | G25: 45529.465 | H25: =IF(F25="", "", NETWORKDAYS.INTL(F25, G25, 11,祝日シート!A:A)) -> 0 | I25: 0.0069444444 | J25: OA端末関連 | K25: 社長 | M25: 尾島社長 | N25: 低 | O25: 完了 | P25: 尾島社長OA端末フリーズ対応 | Q25: タスクマネージャで不要アプリの停止などで動作が復旧。
B26: ="No"&ROW()-3 -> No23 | C26: =IFERROR(IF(G26<>"",TEXT(G26,"yyyymm"),""),"") -> 202408 | D26: 支援 | E26: 伊藤 | F26: 45529.493 | G26: 45529.5 | H26: =IF(F26="", "", NETWORKDAYS.INTL(F26, G26, 11,祝日シート!A:A)) -> 0 | I26: 0.0069444444 | J26: OA端末関連 | K26: 商品部 | M26: 清國 | N26: 低 | O26: 完了 | P26: 清國さん大容量メールの送信をサポート（ギガファイル便の使用） | Q26: 左記の内容で実施。
B27: ="No"&ROW()-3 -> No24 | C27: =IFERROR(IF(G27<>"",TEXT(G27,"yyyymm"),""),"") -> 202408 | D27: 支援 | E27: 伊藤 | F27: 45529.562 | G27: 45529.569 | H27: =IF(F27="", "", NETWORKDAYS.INTL(F27, G27, 11,祝日シート!A:A)) -> 0 | I27: 0.0069444444 | J27: OA端末関連 | K27: 顧客部 | M27: 林田 | N27: 低 | O27: 完了 | P27: 林田さんも同様の質問があり対応 | Q27: 左記の内容で実施。
B28: ="No"&ROW()-3 -> No25 | C28: =IFERROR(IF(G28<>"",TEXT(G28,"yyyymm"),""),"") -> 202408 | D28: 運用 | E28: 伊藤 | F28: 45531.375 | G28: 45531.75 | H28: =IF(F28="", "", NETWORKDAYS.INTL(F28, G28, 11,祝日シート!A:A)) -> 1 | I28: 0.375 | J28: 総務関連 | K28: 顧客部 | M28: 岡本 | N28: 低 | O28: 完了 | P28: 顧客部新入社パート端末キッティング（Docuworks、CTIの設定の資料化、動作確認含む） | Q28: 左記の内容で実施。
B29: ="No"&ROW()-3 -> No26 | C29: =IFERROR(IF(G29<>"",TEXT(G29,"yyyymm"),""),"") -> 202408 | D29: 運用 | E29: 伊藤 | F29: 45531.458 | G29: 45531.479 | H29: =IF(F29="", "", NETWORKDAYS.INTL(F29, G29, 11,祝日シート!A:A)) -> 1 | I29: 0.020833333 | J29: 総務関連 | K29: システム部 | M29: 佐々嶌 | N29: 高 | O29: 完了 | P29: EDI稟議書の作成と修正 | Q29: 左記の内容で実施。
B30: ="No"&ROW()-3 -> No27 | C30: =IFERROR(IF(G30<>"",TEXT(G30,"yyyymm"),""),"") -> 202408 | D30: 支援 | E30: 伊藤 | F30: 45531.5 | G30: 45531.583 | H30: =IF(F30="", "", NETWORKDAYS.INTL(F30, G30, 11,祝日シート!A:A)) -> 1 | I30: 0.083333333 | J30: 業務運用 | K30: 物流部 | N30: 中 | O30: 完了 | P30: 東日本物流 複合機入替作業 設定の残作業を実施 | Q30: 左記の内容で実施。
B31: ="No"&ROW()-3 -> No28 | C31: =IFERROR(IF(G31<>"",TEXT(G31,"yyyymm"),""),"") -> 202408 | D31: 支援 | E31: 伊藤 | F31: 45532.375 | G31: 45532.75 | H31: =IF(F31="", "", NETWORKDAYS.INTL(F31, G31, 11,祝日シート!A:A)) -> 1 | I31: 0.375 | J31: 総務関連 | K31: 顧客部 | M31: 岡本 | N31: 低 | O31: 完了 | P31: 顧客部新入社パート端末キッティング（Docuworks、CTIの設定の資料化、動作確認含む） | Q31: 左記の内容で実施。
B32: ="No"&ROW()-3 -> No29 | C32: =IFERROR(IF(G32<>"",TEXT(G32,"yyyymm"),""),"") -> 202408 | D32: 支援 | E32: 伊藤 | F32: 45532.542 | G32: 45532.667 | H32: =IF(F32="", "", NETWORKDAYS.INTL(F32, G32, 11,祝日シート!A:A)) -> 1 | I32: 0.125 | J32: 業務運用 | K32: 物流部 | N32: 中 | O32: 完了 | P32: 東日本物流 複合機入替作業 設定の残作業を実施 | Q32: ドライバの確認、基幹側は旧ドライバから設定変更し流用？
B33: ="No"&ROW()-3 -> No30 | C33: =IFERROR(IF(G33<>"",TEXT(G33,"yyyymm"),""),"") -> 202408 | D33: 障害 | E33: 伊藤 | F33: 45532.625 | G33: 45532.646 | H33: =IF(F33="", "", NETWORKDAYS.INTL(F33, G33, 11,祝日シート!A:A)) -> 1 | I33: 0.020833333 | J33: OA端末関連 | K33: 商品部 | M33: 清國 | N33: 低 | O33: 完了 | P33: 清國さんEXCELのエラーからのデータ復旧 | Q33: 自動保存から別ディレクトリに保管されたデータから復旧。
B34: ="No"&ROW()-3 -> No31 | C34: =IFERROR(IF(G34<>"",TEXT(G34,"yyyymm"),""),"") -> 202408 | D34: 運用 | E34: 伊藤 | F34: 45533.375 | G34: 45533.75 | H34: =IF(F34="", "", NETWORKDAYS.INTL(F34, G34, 11,祝日シート!A:A)) -> 1 | I34: 0.375 | J34: 総務関連 | K34: 顧客部 | M34: 岡本 | N34: 低 | O34: 完了 | P34: 顧客部新入社パート端末キッティング（Docuworks、CTIの設定の資料化、動作確認含む） | Q34: 左記の内容で実施。
B35: ="No"&ROW()-3 -> No32 | C35: =IFERROR(IF(G35<>"",TEXT(G35,"yyyymm"),""),"") -> 202408 | D35: 支援 | E35: 伊藤 | F35: 45533.583 | G35: 45533.625 | H35: =IF(F35="", "", NETWORKDAYS.INTL(F35, G35, 11,祝日シート!A:A)) -> 1 | I35: 0.041666667 | J35: OA端末関連 | K35: システム部 | N35: 低 | O35: 完了 | P35: WindowsUpdate用の運用方法を確認 | Q35: 個々PCで設定し、部署単位で運用？ スクリプトかレジストリ？ グループポリシー変更でどうにかならないか？
B36: ="No"&ROW()-3 -> No33 | C36: =IFERROR(IF(G36<>"",TEXT(G36,"yyyymm"),""),"") -> 202408 | D36: 支援 | E36: 伊藤 | F36: 45533.708 | G36: 45533.75 | H36: =IF(F36="", "", NETWORKDAYS.INTL(F36, G36, 11,祝日シート!A:A)) -> 1 | I36: 0.041666667 | J36: 総務関連 | K36: 顧客部 | M36: 林田 | N36: 低 | O36: 完了 | P36: 顧客部端末の設置作業、林田さんとの内容確認 | Q36: 設置場所、アプリのライセンスの有無で設置場所を変更。
B37: ="No"&ROW()-3 -> No34 | C37: =IFERROR(IF(G37<>"",TEXT(G37,"yyyymm"),""),"") -> 202409 | D37: 運用 | E37: 伊藤 | F37: 45536.375 | G37: 45536.75 | H37: =IF(F37="", "", NETWORKDAYS.INTL(F37, G37, 11,祝日シート!A:A)) -> 0 | I37: 0.375 | J37: 総務関連 | K37: 物流部 | M37: 相原 | N37: 低 | O37: 完了 | P37: 相原 移動に伴う端末のキッティング | Q37: 左記の内容で実施。
B38: ="No"&ROW()-3 -> No35 | C38: =IFERROR(IF(G38<>"",TEXT(G38,"yyyymm"),""),"") -> 202409 | D38: 障害 | E38: 伊藤 | F38: 45536.458 | G38: 45536.469 | H38: =IF(F38="", "", NETWORKDAYS.INTL(F38, G38, 11,祝日シート!A:A)) -> 0 | I38: 0.010416667 | J38: OA端末関連 | K38: 商品部 | M38: 成川 | N38: 低 | O38: 完了 | P38: 成川 Excelが遅く開けない。（北山も同様） | Q38: xlsx形式→xlsb形式でローカルは作業。NWを切断することで動作が若干改善。365特有の問題？
B39: ="No"&ROW()-3 -> No36 | C39: =IFERROR(IF(G39<>"",TEXT(G39,"yyyymm"),""),"") -> 202409 | D39: 運用 | E39: 伊藤 | F39: 45537.375 | G39: 45537.75 | H39: =IF(F39="", "", NETWORKDAYS.INTL(F39, G39, 11,祝日シート!A:A)) -> 1 | I39: 0.375 | J39: 総務関連 | K39: 物流部 | M39: 相原 | N39: 低 | O39: 完了 | P39: 相原 移動に伴う端末のキッティング | Q39: 左記の内容で実施。
B40: ="No"&ROW()-3 -> No37 | C40: =IFERROR(IF(G40<>"",TEXT(G40,"yyyymm"),""),"") -> 202409 | D40: 障害 | E40: 伊藤 | F40: 45537.458 | G40: 45537.465 | H40: =IF(F40="", "", NETWORKDAYS.INTL(F40, G40, 11,祝日シート!A:A)) -> 1 | I40: 0.0069444444 | J40: 基幹端末関連 | K40: 商品部 | M40: 安形 | N40: 低 | O40: 完了 | P40: 安形基幹端末の映像出力できない状況への対応。 | Q40: 基幹PCがフリーズしていたので再起動とチェックディスク実施。切替器の再読み込み。キーボード、マウスも無線で電池交換。
B41: ="No"&ROW()-3 -> No38 | C41: =IFERROR(IF(G41<>"",TEXT(G41,"yyyymm"),""),"") -> 202409 | D41: 障害 | E41: 伊藤 | F41: 45537.458 | G41: 45537.562 | H41: =IF(F41="", "", NETWORKDAYS.INTL(F41, G41, 11,祝日シート!A:A)) -> 1 | I41: 0.10416667 | J41: OA端末関連 | K41: 商品部 | M41: 成川 | N41: 低 | O41: 完了 | P41: Excelの動作が遅くなる問題について確認。xlsx形式→xlsb形式で動作、容量が軽減1/5程度に。 | Q41: xlsx形式→xlsb形式でローカルは作業。NWを切断することで動作が若干改善。365特有の問題？
B42: ="No"&ROW()-3 -> No39 | C42: =IFERROR(IF(G42<>"",TEXT(G42,"yyyymm"),""),"") -> 202409 | D42: 障害 | E42: 伊藤 | F42: 45537.5 | G42: 45537.542 | H42: =IF(F42="", "", NETWORKDAYS.INTL(F42, G42, 11,祝日シート!A:A)) -> 1 | I42: 0.041666667 | J42: SCAW関連 | K42: 営業管理部 | M42: 堀川 | N42: 低 | O42: 完了 | P42: 堀川 基幹 oracleに接続できない問題。oraファイルの内容が古く接続先が違っていたので修正。 | Q42: 左記の内容で実施。
B43: ="No"&ROW()-3 -> No40 | C43: =IFERROR(IF(G43<>"",TEXT(G43,"yyyymm"),""),"") -> 202409 | D43: 要望 | E43: 伊藤 | F43: 45538.375 | G43: 45538.75 | H43: =IF(F43="", "", NETWORKDAYS.INTL(F43, G43, 11,祝日シート!A:A)) -> 1 | I43: 0.375 | J43: その他 | K43: 営業管理部 | M43: 野崎 | N43: 中 | O43: 完了 | P43: 商品管理部 加藤・田中 情報系端末のScawメニューの付与（設定方法の確認も含む） | Q43: 左記の内容で実施。
B44: ="No"&ROW()-3 -> No41 | C44: =IFERROR(IF(G44<>"",TEXT(G44,"yyyymm"),""),"") -> 202409 | D44: 支援 | E44: 伊藤 | F44: 45538.458 | G44: 45538.479 | H44: =IF(F44="", "", NETWORKDAYS.INTL(F44, G44, 11,祝日シート!A:A)) -> 1 | I44: 0.020833333 | J44: 業務運用 | K44: 物流部 | N44: 中 | O44: 完了 | P44: 物流 複合機の設定の確認 | Q44: 基幹のドライバが新しいものはXPで対応していないので旧ドライバから引継ぎ。まだわからない。
B45: ="No"&ROW()-3 -> No42 | C45: =IFERROR(IF(G45<>"",TEXT(G45,"yyyymm"),""),"") -> 202409 | D45: 運用 | E45: 伊藤 | F45: 45538.5 | G45: 45538.583 | H45: =IF(F45="", "", NETWORKDAYS.INTL(F45, G45, 11,祝日シート!A:A)) -> 1 | I45: 0.083333333 | J45: 業務運用 | K45: システム部 | N45: 低 | O45: 完了 | P45: 資産管理 端末情報の確認作業 | Q45: 台帳とSkyの際が増えてきたので現場と在庫と確認。
B46: ="No"&ROW()-3 -> No43 | C46: =IFERROR(IF(G46<>"",TEXT(G46,"yyyymm"),""),"") -> 202409 | D46: 要望 | E46: 伊藤 | F46: 45538.562 | G46: 45538.569 | H46: =IF(F46="", "", NETWORKDAYS.INTL(F46, G46, 11,祝日シート!A:A)) -> 1 | I46: 0.0069444444 | J46: その他 | K46: 営業管理部 | M46: 野崎 | N46: 中 | O46: 完了 | P46: 商品管理部 加藤・田中 固定電話の受信時の動作の変更作業 | Q46: 部署の先に在籍していた社員の設定を流用、設定し確認。手順を資料化して保存。
...

Sheet 社内機器・ソフト・システムの保守 - 作業内容管理・進捗
B1: システム運営課 社内機器・ソフト・システムの保守 - 作業内容管理・進捗
B3: No. | C3: 課題件名 | D3: 背景 | E3: 対応内容 | F3: 期限 | G3: 状況 | H3: 備考 | I3: 進捗
B4: =ROW()-3 -> 1 | C4: USB使用廃止と中継サーバー方式への完全移行 （USB回収、USBポート無効化、データ移行手順の統一） | D4: 会社全体で複数部署がUSBでデータ移動しており、工数・時間・セキュリティリスクが高い。 中継サーバー方式へ移行済みだが、各部署で所有していたUSBは未回収のため、継続利用の可能性がある。 | E4: 〇中継サーバー方式の標準化・完全移行 ・中継サーバー上で指定フォルダへの投入をトリガに自動転送するPythonプログラムを本番運用。 ・サーバー側にウイルス対策ソフトを導入済みで、投入ファイルのリアルタイムスキャンを有効化（従来のUSB全体スキャン運用と同等のセキュリティ水準を維持）。 ・接続ユーザーを管理し、パスワードは月1で定期変更。不要アカウントは都度無効化。 ・転送ログ、ファイルバックアップ機能あり。 〇USB回収 ・各部署で使用していたUSBの返却を依頼し、回収保管済み。 〇USBポート無効化 ・クライアント管理ツールSkySeaを用いて、システム統括部所属端末を除いて、USBストレージ含む外部メディアの接続を無効化。 ・恒久使用する外部メディアは、SkySeaに登録管理した上で接続を許可する。 ・一時使用する外部メディアは、使用期間を設定した上でSkySeaで一時的に接続を許可する。 | F4: 45777 | G4: 完了 | H4: ・各部署で所有していたUSBメモリの総数は不明だが、届出がない外部メディアはOA/基幹の両端末で一切使用できないため、セキュリティリスクは低いと考える | I4: ・毎月メンテナンスを実施(利用者のパスワード変更、中継サーバへのセキュリティ更新プログラム適用、転送プログラムの再起動等) ・データ移行に関する質問は随時相談可能
B5: =ROW()-3 -> 2 | C5: UPS（無停電電源装置）配線整備 | D5: ・昨年8月の雷による停電（土曜日）発生時、UPS配線の不備により「端末は稼働するがモニターが起動しない」またはその逆の事象が発生し、一時的に業務へ支障が出た。 ・当時は稼働している端末に業務を寄せて対応したが、再発時の業務継続性に課題がある。 | E5: 作業内容：UPS配線の整備 （端末・モニターが同一系統でUPS保護下に入るよう配線見直し、ラベル整備、通電確認） 対象エリア：顧客部の島 事前依頼事項 机の下の整理：作業しやすいよう事前清掃をお願いします 机上の整理：机移動時の落下防止のため、向かい側の机との間に物を置かないでください 作業後対応：通電確認、簡易動作確認（端末・モニター）、不具合時はその場で復旧またはエスカレーション | F5: 実施日時：6月1日（日） | G5: 完了 | H5: 作業中は電源ケーブルの抜き差しを行います。作業開始前に保存・ログオフをお願いします。 | I5: 実施日時：6月1日（日） 配線見直し→ラベリング→通電・表示確認→記録（完了シール/チェックリスト） 全て完了済み。
B6: =ROW()-3 -> 3 | C6: 【セキュリティ対策】 社内端末のパスワード変更 | D6: 昨今のサイバーセキュリティ環境を鑑み、社内システムの安全性をより一層高めるため、 全社員のOA端末のパスワード変更をお願いすることになった。 | E6: 全社員にパスワード変更するよう社内メールで通知。 その際、パスワードを忘れて入れなくならないようシステム管理者ユーザーも作成。 〇新しいパスワードの要件 ・8文字以上の長さ ・英大文字（A〜Z）を1文字以上 ・英小文字（a〜z）を1文字以上 ・数字（0〜9）を1文字以上 ・特殊記号（!@#$%^&*など）を1文字以上 | F6: 45842 | G6: 完了 | H6: ユーザーがパスワードを変更したかどうかは判断できない。 | I6: 案内済み。 システム管理者ユーザーが入っていない端末はその都度作成済み。 パスワードを忘れたユーザーに関してはシステム管理者ユーザーで入り、パスワードを変更できます。
B7: =ROW()-3 -> 4 | C7: データベース操作ツールの移行 | D7: 現在、SQLツールとしてオブジェクトブラウザーを使用していますが、以下の問題がある： 1. バージョンとライセンスの問題 バージョン9、11、12が混在して使用されている バージョン9はライセンスが無制限ですが、 フルアクセスモードのためセキュリティリスクが存在する（ここが一番問題） バージョン11、12のリードオンリー版はセキュリティ面では安全ですが、ライセンス数が限られている 2. ライセンス不足 リードオンリー版のライセンス数が限られているため、全ユーザーに提供できない 今後ユーザー数が増加した場合、対応できない 3. 互換性の問題 新規購入可能な最新バージョンはWindows XPに対応していないため、基幹環境では利用できない 4. 新規ユーザー対応の課題 新しいメンバーがSQLを使いたい場合も、セキュリティ的に問題のあるバージョン9を使わざるを得ない状況 | E7: 今後SQLの導入が必要なユーザーについてはフリーソフトの「A5:SQL」を利用してもらう。 導入と簡単な利用方法の説明はシステム運営課で対応する。 | F7: - | G7: 進行中 | H7: SIOBと若干使い勝手が違うので、その都度システム運営課で対応する。 | I7: A5:SQL導入：３名 SIOB9利用者：３名
A8: . | B8: =ROW()-3 -> 5 | C8: Windows 10サポート終了対応 | D8: Microsoft社のWindows 10のサポートが2025年10月14日に終了予定。 セキュリティ更新が提供されなくなるため、Windows11へアップグレードの対応が必要。 | E8: SkySeaなどを使ってリモートで更新できるか試したが難しい。 ただし、通常なら複数回再起動を促される毎に再起動を手動でやらないといけないものを 一度起動したら最後まで再起動してWindows11までアップグレードできるバッチを作成できそうなので それを使って帰り際にバッチを起動して、翌朝にはWindows11にアップグレードが完了している、というような なるべく業務に支障がでない対応が可能になる予定。 | F8: 45944 | G8: 進行中 | H8: 残存14台につきまして、引き続き計画的な実施スケジュールに基づき、 順次更新を実施していく予定です。 特に共用端末等、利用状況やロケーションに配慮した対応が必要な端末については、関係者と調整のうえ適切なタイミングでの更新を進めていきます。 | I8: 【10/15更新】 93.14%完了 (残14台) システム統括部 19/22台 完了率 86.4%（残3台） マーケティング部 14/14台 完了率100% 営業管理部 21/22台 完了率95.5%（残1台） 営業部 12/12台 完了率100% 管理部 15/15台 完了率100% 顧客部 49/55台 完了率89.10% (残6台) 商品部 15/18台 完了率83.30%（残3台） 物流部 29/30台 完了率96.7%（残1台） 本社役員 5/5台 完了率100% 遊休端末 11/11台 完了率100%
A9: . | B9: =ROW()-3 -> 6 | C9: Office 2019サポート終了対応 | D9: Office 2019(OA端末80台)のサポートが2025年10月14日に終了予定。 セキュリティ更新が提供されなくなるため、アップグレードが必要。 | E9: Officeの更新(購入)が必要。 2019の後継ソフトはOffice2024だが、サポートが5年(2029年)なので月毎の費用を計算すると サブスクリプションであるOffice365とあまり変わらないのと、Office365は常に機能が更新され 人によってエクセルのバージョンが違うことによる弊害の心配もないのでOffice365の導入の決定となった。 (稟議決裁済み) 古い2019を削除して新しいWindows365を自動的にインストールできるバッチを作成済み。 各部署と連携して順次更新をしていく。 | F9: 45944 | G9: 完了 | I9: 【完了】Office2024買い切り版 or MS365の導入方針決め 【完了】MS365追加ライセンス数の精査 【完了】富士フィルムBIJへライセンス追加申請、管理サイト上での割当数確認 【完了】Office2019の削除、MS365のインストールの実行スクリプト作成、検証 【完了】対象端末インストール実行（88/88台 100%完了済み）
A10: . | B10: =ROW()-3 -> 7 | C10: OAネットワーク新回線敷設 | D10: 毎月第二火曜日の翌日（WindowsUpdate配信日）朝の時間帯にインターネット接続が遅延して業務影響がある。 現行のOAネットワーク回線はPPPoE接続方式のため混雑の影響を受けやすく、IPoE方式へ変更する。 | E10: 本社インターネット接続の主回線として新規NUROアクセススタンダードを契約する（10Mbps帯域保証） 主回線トラブル時の予備として現OCN回線を保持するが、予備へ切り替える際の運用上、プライベートIPアドレス（10.85.32.0/23）の使用が必須となるため、新回線開通に合わせて本社設置端末のIPアドレスを変更する。 また新回線で割当されるグローバルIPアドレスを確認して、IP制限を行っているサイト、サービスへ登録する | F10: 2025/12末 | G10: 完了 | I10: 【完了】 ～9月末 新回線申込、本社一部端末のIPアドレス変更 【完了】～10月末 本社全端末のIPアドレス変更(10/20～24)、回線工事事前調査(10/28) 【完了】～11月末 新回線のグローバルIPアドレスの確認、各種IP制限サイトへの登録 【完了】12月以降 本社NW作業実施、新OA回線利用開始
B11: =ROW()-3 -> 8 | C11: アーカイブソフトウェア「Lhaplus」の廃止と「7-Zip」の利用推進 | D11: 全社OA端末で利用されている「Lhaplus」は2017年で開発が停止しており、現在一部の圧縮方式で脆弱性が存在することが判明している。解凍時に文字化けが発生するなど機能的な問題もあり、代替ソフトウェアとして「7-Zip」への移行を推進する。 | E11: OA端末上で「Lhaplus」のインストール有無を調査して削除、「7-Zip」をインストールするツールを作成し、全社展開する。 | F11: 2025/12末 | G11: 完了
B12: 9 | C12: 自動封函機と物流サーバー間のデータ連携 | D12: 物流センターに導入される封函機、仕分け機稼働のため、物流サーバーと出荷実績、出荷指示の各データの受け渡しを行うネットワークを構築する | E12: ・封函機メーカー側で外部から機器動作状況の確認を行うため、インターネット接続環境構築する ・封函機側のネットワーク環境と当社基幹ネットワークを分離し、ネットワーク間にNASを 配置してSFTPプロトコルのみ許可する方式とする | F12: 46064 | G12: 進行中 | I12: ・外部ネットワーク接続は不要（問題発生時はメーカー側の駆けつけ対応） ・EXVへのネットワーク構築作業の発注が遅延したため、NASの代替とする 基幹PCを構築配置して、データ受け渡しを実行中 ・NASへの切り替えは、3/5に実施したが検証中にNASの不具合があり 調査中 ・３月中旬の調査の過程で不具合が解消、切替作業時に封函機メーカー側の立ち合いが必要なため、スケジュール調整中
B13: 10 | C13: 本社休憩室へのWi-Fi環境構築 | D13: 社長、信川専務の座談会から休憩室でWi-Fiが使用したいとの要望があり対応 | E13: モバイルルータを設置する案、業務用のOA予備回線を使用する案など検討したが、コスト面をクリアしたため、新たにOCN回線を契約して使用する | F13: - | G13: 完了 | I13: ・2025/11：当時案の相談あり、検討開始 ・2025/12：OA予備回線流用案を含めてEXVへ見積もり提出、合わせて東日本物流センターでも休憩室への導入を検討 ・2026/1：EXVへの発注、現地調査および工事日程調整開始 ・2026/2：回線工事完了、利用開始（東日本物流センターは見送り）
B14: 11 | C14: GoogleWorkspaceの導入支援 | D14: Geminiによる業務効率化推進、既存の全社コミュニケーションツール（メール、メッセージ、掲示板、ファイル共有）の見直し | E14: システム部としては以下を業務スコープとする ■システム対応 アカウント発行、データ移行設計、セキュリティ設定、 （既存システム（サイボウズ等）との併用設定） | F14: - | G14: 進行中 | H14: https://docs.google.com/spreadsheets/d/1hdokrHlTowNvE1OUsHEKj0O6p0VMtt4R1OhtIilolZc/edit?gid=1292048900#gid=1292048900 | I14: ・アカウント発行：利用対象ユーザーへのアカウント発行完了（4/13時点） ・データ移行設計：Gmailへのメールデータ移行方法を調査し対応中。サイボウズメッセージはエクスポート機能がないため、全件テキスト出力するツール（PythonによるWebページ操作）を開発試験中
B15: 12 | C15: 本社OAネットワークの機器・回線障害時の切替簡易化 | D15: No.7の関連。予備回線と本回線で個別のゲートウェイアドレスを持つ構成であったため、予備回線への切り替え時に既存の手順（LANケーブルの差替え）での運用とするための対応 | E15: ルータ設定を変更して統一のゲートウェイアドレスとし、ケーブル抜線結線による切替方式とした | F15: - | G15: 完了 | I15: ・3/18に切替作業を実施していたが、１本のケーブルの差替えで完了する構成に見直すため、3/25に再作業して完了。 ・作業後にOCNで払い出されるDNSアドレスを設定している端末がインターネット接続不可となる障害が発生。公開DNSサーバーである8.8.8.8や1.1.1.1を設定して対処完了
B16: 13 | C16: 従来のOA・基幹の各共有フォルダ内データのNASへの移行 | D16: OA側は共有元のMS02Y-Nサーバーの保守解約のため、基幹側は空き容量枯渇のため、既存の共有ファイルをNASへ移行する | E16: OA側：移行アナウンス後、サーバー上でフォルダ共有を解除する 基幹側：システム上必要なフォルダ以外をNASへ移行 | F16: 2026/3末 | G16: 進行中 | I16: ・4/1にOA共有フォルダの共有停止を行ったが、配送部の移行が未完了であったため共有停止は延期 ・順次基幹NASへの移行が進行。各部のショートカットファイルやツールの呼び出し先が共有フォルダに指定されているため、変更対応中
B17: 14 | C17: NTT東日本と保守契約しているネットワーク機器の更改対応 | D17: フォーレスト各拠点と取引先を接続するVPNルータについて、メーカーサポート切れにより、保守契約を一時解約したいとの申し出があり、機器更改した上で再度保守を依頼する | E17: 計12台の機器リプレイスと保守契約の見積もりを取得して発注および工事予定。 リプレイスは対象の拠点、取引先で一斉に実行するため、スケジュールの調整が必要。 | F17: ー | G17: 進行中 | I17: 見積算出にリプレイス作業の開始時間の提示が必要。関係部署と調整が必要。
B18: 15 | C18: Bizストレージファイルシェアの導入 | D18: 顧客、取引先とのファイル共有において、PASS付きZipファイルによるメール添付とパスワード通知という手段が慣習化しているが、誤送信など情報漏洩リスクがあり、クラウドサービスの利用でリスク低減を図る | E18: Bizストレージファイルシェアを導入して、原則メールへのファイル添付は禁止とする | F18: ー | G18: 完了
B19: 16 | C19: 北浦和データセンターの保守切れサーバーの撤去、旧FAXOCRサーバーのHDD増設および福岡システム開発室移送 | D19: 保守契約が終了しているサーバー6台について、将来的な新サーバーのラッキングスペースを確保するため撤去する。また旧FAXOCRサーバー2台および旧W-FL03サーバーは開発用サーバーとして転用する。 | E19: 旧FAXOCRサーバーは福岡システム開発室へ移送、新開発用サーバーとして構築中。 旧W-FL03サーバーは大宮本社のサーバーラックに配置して、Win2016評価版を導入し各種検証サーバーとして活用する | F19: ー | G19: 完了
B20: 17 | C20: WEBアプリケーションサーバー更改 | D20: 現行WEBアプリケーションサーバーのアクセス数増加対応、メモリーリークによる不定期シャットダウン解消に向け、サーバーリプレイスを行う。 | E20: リプレイスに伴い、以下を行う ・サーバーのハードウェア構成確認 ・WindowsServer設定シートの記載確認 ・北浦和データセンターのラッキングスペースの確保 ・既存ネットワークスイッチとの接続作業および暫定構成検討 ・ルーティングテーブル、NTP、SMB1.0無効化など追加設定 | F20: ー | G20: 進行中 | I20: 5/13サーバ搬入予定、それまでにネットワークスイッチへのLANケーブル接続を内製で対応予定
B21: 18 | C21: 新CTI対応 | D21: 現行のCTIシステムの交換機AspireUXが保守期限切れとなっており、新しい交換機と電話機にリプレイスする | E21: 下村部長、CTI構築ベンダーと連携して新電話機の内線番号設定や現場検証を進める | F21: ー | G21: 進行中 | I21: 新電話機の設定は完了。新CTI端末が準備出来次第、新交換機での業務試験を実施予定
B22: 19 | C22: EDION社員用・予備機PCキッティング | D22: EDION出向社員がGWSのポータルがノートPCで会議などで閲覧できないので ノートPCを支給してほしいとの要望。 | E22: 見積もり（使用方法に対して金額が高いので中古）・稟議・キッティング作業。 ７台購入し対応。（中古で購入だが１台が不具合あり。修理のために返送。戻り次第予備機として キッティングの予定。必要なEDION社員には配布したので一旦終了とする。 | F22: ー | G22: 完了 | H22: 中古の品質はイオシスのほうがAmazonより上。故障があったが 対応の柔軟性もイオシス。 個別に設定が複雑化しており、キッティングの基本部分は スクリプトで短縮できたが全体の時間は増加。６台16.5時間４日。
B23: 20 | C23: PCモニタ2台・LANケーブル、 スイッチングハブ購入 | D23: モニターは人員増加で2台をすぐ使用予定。LANケーブルは在庫がなくなったので追加購入。 窓際の重役席のHubがないので購入。 | E23: モニターは見積もり、稟議、EDIONクロスベンチャーズに発注。 LAN、ハブはForestwayで購入。 | F23: 46174 | G23: 完了 | H23: 入荷後、必要個所に配布、設置。
B24: 21 | C24: 商品部 梅森社員の基幹端末キッティング | D24: WindowsXPの在庫がないため在庫していたWin10のPCを使用し基幹端末を制作。 | E24: CTI導入の予定に合わせてVM-wareを使用した仮想化。マスタのvmdk化や設定を調査し、 仮想化での課題の抽出と手順化もかねて対応。 | F24: 46185 | G24: 完了 | H24: VM-wareなら設定が容易。HDD仕様、８GBメモリでもSCAWのみなら動作がそれほど重くない。ホスト起動後にゲストの自動起動と画面最大化もクリア。
B25: 22 | C25: 商品部商品管理課 野崎社員の基幹端末キッティング | D25: Windows11の環境下で基幹端末を作成し、ホスト側で基幹データをPythonを使用し処理したい。そのため仮想化した基幹端末を作成。 | E25: 工場出荷状態のWindows10端末から専用ISOファイルを作成しクリーンインストール（更新の時間を削減） そこからVM-Wareでの構築。問題抽出。 | F25: 46202 | G25: 完了 | H25: 引渡し済み。課題：ホスト側のOfficeソフトのオフラインインストール、VM用のデータ抽出の時間（300GBで8時間弱）、vmdkへの変換（1.5時間）など。また個別に問題点が出てくるものの対応が必要。抽出から付与までの期間のデータの差分解消方法の検討。
C26: 物流 浅野部長、三嶋部長社用スマホへの機種変更 | D26: GWS導入で外出、倉庫内にいるときに情報を確認するためにガラケーからスマホへの機種変更を希望。 | E26: Android端末2台の新規見積もりおよび納期情報の依頼。 | F26: 46213 | G26: 完了
C27: 福岡開発室 開発用モニター試験導入のための購入 | D27: 田中役員から開発現場で効率化を図るために購入の希望。 | E27: 福岡AI開発環境用として31インチ以上・高解像度モニターの提案・見積を依頼。EXV宮澤様に見積もり、社内稟議作成の代行、発注業務。 | F27: 46204 | G27: 完了
C28: 名刺印刷室UPSバッテリー購入 | D28: 5年経過のUPSバッテリーの寿命から通知が発されたため、交換に至る。 | E28: 名刺印刷室UPS バッテリー劣化でエラー。 EXV宮澤様に見積もり、Amazonと比較し、社内稟議。 Amzonで購入。交換済み。 | F28: 46206 | G28: 完了
C29: （GWS関連対応）EDION社員用PC購入、キッティング | D29: 亀澤社員、深澤社員、外山社員用OA端末購入の件。 管理部よりGWS導入で外出、会議で使用するためデスクトップPCから変更の要請のため。 | E29: イオシスで見積もり、稟議、購入後にキッティングし配布。（7/1～7/7） 外山社員はリカーズAKIBAに郵送処理。 | F29: 46211 | G29: 完了
C30: 福岡開発室 西島社員ガラケー貸与 | D30: 田中役員休職時に、緊急連絡を取れる体制構築のため。 | E30: 福岡（西島さん用）に在庫ガラケーを初期化し発送対応。チャットで福岡に連絡。 | F30: 46202.614 | G30: 完了
C31: 仮想基幹端末用Office2019運用 | D31: 基幹端末仮想化で社内で使用していないOffice2019で既存の2010より効率化が図れる可能性。ライセンスが余っているのでオフラインで使用、認証が可能か調査。 | E31: 仮想端末で使用するOffice 2019のKMSホストキーに関する問い合わせ。 オフラインインストーラーの作成を実施。 富士フィルム 仲居様 | F31: 46203.376 | G31: 進行中 | H31: 追加でライセンスの購入が必要。返信待ち。
C32: 社長室ミーティングスペース31.5インチPCモニター購入 | D32: 社長室ミーティングスペースで大型のモニターでPC画面を表示させて打ち合わせ等を行いたい。 | E32: 本社社長室で使用するモニター1台分の正式見積書作成依頼 EXV宮澤様に見積もり、発注業務。7/2～7/14 | F32: 46217.376 | G32: 進行中
C33: （GWS関連対応）役職者用PC購入、キッティング | D33: 管理部より野崎、北澤、岡本社員用中古OAノートPC購入の件で依頼。 GWS導入で外出、会議で使用するためデスクトップPCから変更の要請のため。 | E33: イオシスで見積もり、稟議、購入後にキッティングし配布。 | F33: 46217.376 | G33: 進行中 | H33: 7/14稟議書作成中
C34: 新入社員受け入れ対応 | D34: 7月派遣社員の受け入れ準備のため。 | E34: 7月中旬入社予定の派遣社員用端末のOffice365ライセンス追加依頼。 チャットで坂田部長に依頼。 | F34: 46216 | G34: 完了 | H34: 7/14 納品待ち
C35: 新入社員受け入れ対応 | D35: 7月派遣社員の受け入れ準備のため。 | E35: 7月中旬入社予定の派遣社員用、OA、基幹端末、備品の準備。 キッティングし一式そろえて設置の予定。 | F35: 46219 | G35: 進行中 | H35: 7/14 90％完了
C36: 組織変更による端末準備対応 | D36: 体制変更のため管理部からの依頼。 | E36: 管理部依頼の新規OA端末用ノートPCの見積もり、モニター3台の見積もり EXV宮澤様に見積もり、社内稟議作成の代行、発注業務。 | F36: 46219 | G36: 進行中 | H36: 7/14 見積り依頼済み
C37: （GWS関連対応）OA端末スペックアップ | D37: GWS導入でメモリ不足が顕著に発生するため管理部に提出用のメモリ増設計画の資料作成 | E37: SkySeaから８GBメモリ端末を抽出。価格調査、設置方法を明示。 | F37: 46219 | G37: 進行中 | H37: 提出待ち
A59: .

Sheet 2604変更前　ヘルプデスク - 作業内容管理・進捗
C1: システム運営課 ヘルプデスク - 作業内容管理・進捗
B3: No | C3: 1.分類 | D3: 2.担当者 | E3: 3.日付 | F3: 4.発生時刻 | G3: 5.終了時刻 | H3: 6.実作業時間 | I3: 7.終了予定日 | J3: 8.完了日付 | K3: 9.ジャンル | L3: 10.依頼部署 | M3: 11.依頼部署 | N3: 12.依頼主 | O3: 13重要度 | P3: 14.ステータス | Q3: 15.問題事象・作業内容 | R3: 15.対応内容
B4: ="No"&ROW()-3 -> No1 | C4: 障害 | D4: 伊藤 | E4: 45778 | F4: 0.375 | G4: 0.37847222 | H4: 0.0034722222 | I4: 45778 | J4: 45778 | K4: OA端末関連 | L4: 営業部 | N4: 佐藤 | O4: 低 | P4: 完了 | Q4: OA端末のログイン時のエラー。画面が黒くなりマウスカーソル以外見えなくなる。 | R4: Ctrl＋Alt＋Deleteキーでサインアウトし再度ログインすると正常動作でログインできるようになるので解消。Windows11 24H2の障害か？ FMVで多発する。
B5: ="No"&ROW()-3 -> No2 | C5: 障害 | D5: 伊藤 | E5: 45772 | F5: 0.33333333 | G5: 0.375 | H5: 0.16666667 | I5: 45778 | J5: 45778 | K5: OA端末関連 | L5: 物流部 | N5: 山中 | O5: 中 | P5: 完了 | Q5: 川口3階のアルバイト・パート社員打刻PCの不調、Freeeの打刻アプリの更新ができない。リモート接続できず本社に送り対応。 | R5: SSDの不良がありコピーし移植。BIOSなどの更新含め対応。管理部でFreeeの設定を行い発送。設置後にテストをしてもらい、完了。
B6: ="No"&ROW()-3 -> No3 | C6: 要望 | D6: 伊藤 | E6: 45778 | F6: 0.375 | G6: 0.38194444 | H6: 0.0069444444 | I6: 45778 | J6: 45778 | K6: 総務関連 | L6: 管理部 | N6: 関口 | O6: 低 | P6: 完了 | Q6: 新入社員 沖田さんのメールアカウントの作成と、サイボウズ への登録・確認。 | R6: 左記の内容
B7: ="No"&ROW()-3 -> No4 | C7: 障害 | D7: 伊藤 | E7: 45778 | F7: 0.47916667 | G7: 0.70486111 | H7: 0.03125 | I7: 45778 | J7: 45778 | K7: OA端末関連 | L7: 川口配送センター | N7: 中澤 | O7: 中 | P7: 完了 | Q7: 中澤さんOA端末 Win11に更新によるものでスキャンボックスに入る際に、 認証が必要となり使用できない。 | R7: 本社から配送センターの複合機に管理者ログイン。ボックス内の中澤アカウントにパスワードを設定しテスト。11からWindows資格情報にIP、ボックス番号、パスワード設定が必須。総務人事からのフォルダに資料を保管。
B8: ="No"&ROW()-3 -> No5 | C8: 要望 | D8: 坂本 | E8: 45778 | F8: 0.41666667 | G8: 0.625 | H8: 0.041666667 | I8: 45786 | J8: 45792 | K8: OA端末関連 | L8: 顧客部 | N8: 遠藤 | O8: 低 | P8: 完了 | Q8: オーダーメイドで使用する外付けHDDが認識不可 | R8: ①外付けHDDを接続する端末を、USBストレージの制限対象外とする ②外付けHDD自体を使用許可するメディアとしてSKYSEA登録して①を解除する
B9: ="No"&ROW()-3 -> No6 | C9: 障害 | D9: 坂本 | E9: 45778 | F9: 0.4375 | G9: 0.70833333 | I9: 45779 | K9: その他 | L9: 顧客部 | N9: 村本 | O9: 中 | P9: 完了 | Q9: 名刺端末でスキャンしたデータが名刺サーバ上(\\flbc01\MEISHI_LOGO\OUT)に存在せず、また見覚えのないデータが存在する | R9: 社内メールで福岡へ調査依頼 →名刺ロゴ抽出のプログラムが、動作中の状態に見えて一部機能に不具合が発生。プログラムを再起動して解消。
B10: ="No"&ROW()-3 -> No7 | C10: 支援 | D10: 伊藤 | E10: 45778 | F10: 0.70833333 | G10: 0.72222222 | H10: 0.013888889 | I10: 45778 | J10: 45778 | K10: 総務関連 | L10: 管理部 | N10: 坂田 | O10: 中 | P10: 完了 | Q10: Bizストレージ＆ファイルシェア 見積書＆申込書の申し込み・疑問点の確認のためNTTコールセンター担当者と電話。 | R10: 見積書・申込書はExelファイルでZipファイルでメールで受信予定。週明け。 担当：清水様 0120-950-138
B11: ="No"&ROW()-3 -> No8 | C11: 支援 | D11: 伊藤 | E11: 45778 | F11: 0.72222222 | G11: 0.72916667 | H11: 0.0069444444 | I11: 45778 | J11: 45778 | K11: その他 | L11: 営業管理部 | N11: 津田 | O11: 低 | P11: 完了 | Q11: iPad 業務用アプリケーション更新作業の手順の確認 | R11: Apple IDを入力し対応。2要素認証が管理部部長だった岡村さんに行くのでGWに修正し変更する予定。
B12: ="No"&ROW()-3 -> No9 | C12: 課題 | D12: 伊藤 | E12: 45778 | F12: 0.41666667 | G12: 0.4375 | H12: 0.020833333 | I12: 45778 | J12: 45778 | K12: その他 | L12: システム部 | N12: 下村 | O12: 低 | P12: 完了 | Q12: KPIや業績評価で必要な運営課の作業内容を入力するシートの作成（本シート） | R12: 作成完了。下村さんにパスを共有するメール。
B13: ="No"&ROW()-3 -> No10 | C13: 問合せ | D13: 佐々嶌 | E13: 45778 | F13: 0.72916667 | G13: 0.73611111 | H13: 0.0069444444 | I13: 45778 | J13: 45778 | K13: その他 | L13: 営業部 | N13: 見形 | O13: 中 | P13: 完了 | Q13: メモ番号:36065967の内容が自動的？に入っているが、メールが届いていない。メモ内容がメールと自動連携されているのでメールがあるはず、とのこと。 | R13: よくわからないので下村さんにお願いしました。
B14: ="No"&ROW()-3 -> No11 | C14: 問合せ | D14: 坂本 | E14: 45779 | F14: 0.59375 | G14: 0.60416667 | H14: 0.010416667 | I14: 45779 | J14: 45779 | K14: 基幹端末関連 | L14: 物流部 | N14: 浅野 | O14: 中 | P14: 完了 | Q14: 基幹データ移動の際、中継サーバに接続不可。 | R14: 128.128.5.6のみ疎通ができない状態。再起動後に状況を確認しようとしたが、浅野さんに端末制御が移ったため、メールで接続確認を依頼。
B15: ="No"&ROW()-3 -> No12 | C15: 要望 | D15: 坂本 | E15: 45779 | F15: 0.54166667 | G15: 0.55208333 | H15: 0.010416667 | I15: 45779 | J15: 45779 | K15: OA端末関連 | L15: 物流部 | N15: 名塚 | O15: 中 | P15: 完了 | Q15: OA端末192.176.5.11でUSBメモリの接続許可依頼 | R15: SKYSEAで接続許可対応
B16: ="No"&ROW()-3 -> No13 | C16: 支援 | D16: 佐々嶌 坂本 | E16: 45779 | F16: 0.79166667 | G16: 0.75 | H16: 0.33333333 | I16: 45786 | J16: 45786 | K16: 開発 | L16: 顧客部 | N16: 野尻 | O16: 中 | P16: 完了 | Q16: ライフル買い物コネクトで欠品商品を抽出するツールの仕様変更 | R16: 要望通り対応
B17: ="No"&ROW()-3 -> No14 | C17: 支援 | D17: 佐々嶌 | E17: 45784 | F17: 0.65625 | G17: 0.76041667 | H17: 0.10416667 | I17: 45784 | J17: 45784 | K17: その他 | L17: 商品部 | N17: 安形 | O17: 高 | P17: 完了 | Q17: エディオン財務部 配信用のエクセルの集計シートのデータが月毎のシートの合計と合わないので調査して修正してほしいとのこと。急ぎ。 | R17: 各月のシートのカテゴリが毎月変わっているので、集計シートは対象の全カテゴリを含めないと正しい値にならない。修正済み。
B18: ="No"&ROW()-3 -> No15 | C18: 障害 | D18: 伊藤 | E18: 45784 | F18: 0.375 | G18: 0.38194444 | H18: 0.0069444444 | I18: 45784 | J18: 45784 | K18: OA端末関連 | L18: 顧客部 | N18: 池田 | O18: 低 | P18: 完了 | Q18: OA端末のログイン時のエラー。画面が黒くなりマウスカーソル以外見えなくなる。 | R18: Ctrl＋Alt＋Deleteキーでサインアウトし再度ログインすると正常動作でログインできるようになるので解消。Windows11 24H2の障害か？ FMVで多発する。
B19: ="No"&ROW()-3 -> No16 | C19: 障害 | D19: 坂本 | E19: 45786 | F19: 0.35416667 | G19: 0.36111111 | H19: 0.0069444444 | I19: 45786 | J19: 45786 | K19: OA端末関連 | L19: 顧客部 | N19: 村本 | O19: 低 | P19: 完了 | Q19: OA端末のログイン時のエラー。画面が黒くなりマウスカーソル以外見えなくなる。 | R19: Ctrl＋Alt＋Deleteキーでサインアウトし再度ログインすると正常動作でログインできるようになるので解消。Windows11 24H2の障害か？ FMVで多発する。
B20: ="No"&ROW()-3 -> No17 | C20: 課題 | D20: 坂本 | E20: 45786 | F20: 0.35416667 | G20: 0.41666667 | H20: 0.041666667 | I20: 45786 | J20: 45786 | K20: 開発 | L20: 顧客部 | N20: 林田 | O20: 高 | P20: 完了 | Q20: 母の日ギフト商品の業務支援ツールで、社外モールにアップロードするデータに既定外のデータ項目が出力される | R20: ｄショッピング向けのCSVデータで各行末尾に空データが存在するため、削除する仕組みを追加。
B21: ="No"&ROW()-3 -> No18 | C21: 問合せ | D21: 佐々嶌 | E21: 45789 | F21: 0.43055556 | G21: 0.4375 | H21: 0.0069444444 | I21: 45789 | J21: 45789 | K21: OA端末関連 | L21: 物流部 | N21: 浅野 | O21: 中 | P21: 完了 | Q21: OAから基幹へのファイル転送に失敗する | R21: フォルダでの移動を実施したため、転送ができなかった。ファイル個別での転送を依頼。
... B46: ="No"&ROW()-3 -> No43 | C46: 要望 | D46: 伊藤 | E46: 45792 | F46: 0.58333333 | G46: 0.59722222 | H46: 0.013888889 | I46: 45792 | J46: 45792 | K46: OA端末関連 | L46: 社長 | N46: 尾島社長 | O46: 低 | P46: 完了 | Q46: マーケティング部が使用しているチャート作成ソフトの代替になるような簡単な操作のものがないか質問。 | R46: ひとまず今のものに変わる簡単な操作のものがなく、様子見。引き続き調査。
B47: ="No"&ROW()-3 -> No44 | C47: 要望 | D47: 伊藤 | E47: 45792 | F47: 0.625 | G47: 0.64583333 | H47: =G47-F47 -> 0.020833333 | K47: 基幹端末関連 | L47: 物流部 | N47: 山中 | O47: 低 | P47: 完了 | Q47: 川口3階にあるプリンターを基幹端末にNW接続したい。 EPSONPX105 | R47: 接続方法の確認。ドライバーの準備、IPアドレスの払い出しなど。月曜日に実施。 Forestwayで購入のLANケーブルが届いてからの作業を実施。→希望のLANケーブルが納品がまだ。 →納品されたので完了済み。
B48: ="No"&ROW()-3 -> No45 | C48: 要望 | D48: 佐々嶌 | E48: 45793 | F48: 0.38888889 | G48: 0.39930556 | H48: 0.010416667 | I48: 45793 | J48: 45793 | K48: 基幹端末関連 | L48: 営業管理部 | N48: 大澤 | O48: 低 | P48: 完了 | Q48: インプロのアドミニストレーターバージョンをインストールしたい。 | R48: インストールしました。
B49: ="No"&ROW()-3 -> No46 | C49: 障害 | D49: 佐々嶌 | E49: 45793 | F49: 0.40138889 | G49: 0.40277778 | H49: 0.0034722222 | I49: 45793 | J49: 45793 | K49: OA端末関連 | L49: 営業管理部 | N49: 三縞 | O49: 低 | P49: 完了 | Q49: モニタが映らなくなった。 | R49: 電源が抜けてました。
B50: ="No"&ROW()-3 -> No47 | C50: 要望 | D50: 坂本 | E50: 45793 | F50: 0.46875 | G50: 0.47916667 | H50: 0.0069444444 | I50: 45793 | J50: 45793 | K50: 業務運用 | L50: 顧客部 | N50: 北澤 | O50: 中 | P50: 完了 | Q50: 在庫引き当て | R50: 既定手順で対応済
B51: ="No"&ROW()-3 -> No48 | C51: 要望 | D51: 坂本 | E51: 45793 | F51: 0.48263889 | G51: 0.48958333 | H51: 0.0034722222 | I51: 45793 | J51: 45793 | K51: 業務運用 | L51: 営業部 | N51: 佐藤 | O51: 中 | P51: 完了 | Q51: 出荷予定日変更 | R51: 既定手順で対応済
B52: ="No"&ROW()-3 -> No49 | C52: 要望 | D52: 坂本 | E52: 45793 | F52: 0.55208333 | G52: 0.55902778 | H52: 0.0069444444 | I52: 45793 | J52: 45793 | K52: 業務運用 | L52: 営業部 | N52: 見形 | O52: 中 | P52: 完了 | Q52: 着日変更、出荷指示依頼 | R52: 直送品の着日変更可否を下村さんに確認し、対応いただいた
B53: ="No"&ROW()-3 -> No50 | C53: 支援 | D53: 佐々嶌 | E53: 45794 | F53: 0.52777778 | G53: 0.54861111 | H53: 0.020833333 | I53: 45794 | J53: 45794 | K53: 配送 | L53: 川口配送センター | N53: 小林 | O53: 高 | P53: 完了 | Q53: 新砂午後便の配車確定が定時に間に合わなかった。 | R53: 自動配車を停止して、配車できる状態に変更。 その後確定してもらって、自動配車状態へ移行させた。
B54: ="No"&ROW()-3 -> No51 | C54: 要望 | D54: 伊藤 | E54: 45793 | F54: 0.375 | G54: 0.66666667 | H54: 0.083333333 | I54: 45799 | J54: 45793 | K54: OA端末関連 | L54: 商品部 | N54: 成川 | O54: 低 | P54: 完了 | Q54: Google Cheromeの設定がデスクトップの時のものにそろえたい。 | R54: 完全に本人の要望のため協力はしたが自分で調査させて残りは本人に対応させる。
B55: ="No"&ROW()-3 -> No52 | C55: 課題 | D55: 伊藤 | E55: 45793 | F55: 0.45833333 | G55: 0.47916667 | H55: 0.020833333 | I55: 45793 | J55: 45793 | K55: 総務関連 | L55: 管理部 | N55: 坂田 | O55: 中 | P55: 完了 | Q55: コールセンター年間スケジュール登録による留守電のCTIへの設定の依頼調整。 | R55: 見積もり取得、登録スケジュールの伝達。スケジュールの確定。5/21 10：00 メール・電話対応。
B56: ="No"&ROW()-3 -> No53 | C56: 問合せ | D56: 佐々嶌 | E56: 45796 | F56: 0.67013889 | G56: 0.67708333 | H56: 0.0069444444 | I56: 45796 | K56: OA端末関連 | L56: 管理部 | N56: 上村 | O56: 低 | P56: 完了 | Q56: エクセルを開くとエラーが出ることがある。 閉じれば使えるが、対処方法があれば教えて欲しい。 | R56: https://qiita.com/misty299/items/07700bee14499222d814 「C:\Users\FMV\AppData\Local\Packages\Microsoft.AAD.BrokerPlugin_cw5n1h2txyewy」内のファイルを削除、MS365アカウントで再ログイン
B57: ="No"&ROW()-3 -> No54 | C57: 要望 | D57: 坂本 | E57: 45796 | F57: 0.41319444 | G57: 0.42013889 | H57: 0.0069444444 | I57: 45796 | J57: 45796 | K57: 業務運用 | L57: 顧客部 | N57: 久楽 | O57: 中 | P57: 完了 | Q57: 在庫品の出荷指示依頼 | R57: 在庫品の対応は手順不明のため、下村さんへ連絡。対応中に自動出荷指示がかかった。
B58: ="No"&ROW()-3 -> No55 | C58: 要望 | D58: 坂本 | E58: 45796 | F58: 0.45833333 | G58: 0.46527778 | H58: 0.0069444444 | I58: 45796 | J58: 45796 | K58: 業務運用 | L58: 営業管理部 | N58: 三縞 | O58: 中 | P58: 完了 | Q58: 混載設定追加 | R58: 既定手順で対応済
B59: ="No"&ROW()-3 -> No56 | C59: 要望 | D59: 坂本 | E59: 45798 | F59: 0.39583333 | G59: 0.41666667 | H59: 0.0069444444 | I59: 45798 | J59: 45798 | K59: 業務運用 | L59: 営業部 | N59: 佐藤 | O59: 中 | P59: 完了 | Q59: 出荷予定日変更 | R59: 既定手順で対応済
B60: ="No"&ROW()-3 -> No57 | C60: 要望 | D60: 坂本 | E60: 45798 | F60: 0.40625 | G60: 0.47916667 | H60: 0.0069444444 | I60: 45798 | J60: 45798 | K60: 業務運用 | L60: 営業管理部 | N60: 三縞 | O60: 中 | P60: 完了 | Q60: 混載設定追加 | R60: 既定手順で対応済
B61: ="No"&ROW()-3 -> No58 | C61: 要望 | D61: 坂本 | E61: 45798 | F61: 0.45833333 | G61: 0.46180556 | H61: 0.0034722222 | I61: 45791 | J61: 45791 | K61: 業務運用 | L61: 営業部 | N61: 見形 | O61: 中 | P61: 完了 | Q61: 直送品出荷指示 | R61: 既定手順で対応済
B62: ="No"&ROW()-3 -> No59 | C62: 課題 | D62: 伊藤 | E62: 45798 | F62: 0.72916667 | G62: 0.79166667 | H62: 0.0625 | I62: 45804 | K62: 業務運用 | L62: システム部 | O62: 高 | P62: 完了 | Q62: EDI端末のバックアップ制作。5/21HDDコピー。起動確認。LANアダプタ購入。 | R62: ひとまずコピー＆HDDの動作は確認。この後、PCを完全に予備用のものにして、LANアダプタの到着後に、サーバー室設置。福岡に引き渡してチェックをしてもらう予定。 →タスクスケジューラーの内容を改めて確認して、NWに接続してOKになってから。
B63: ="No"&ROW()-3 -> No60 | C63: 課題 | D63: 伊藤 | E63: 45799 | F63: 0.375 | K63: 業務運用 | L63: システム部 | O63: 高 | P63: 進行中 | Q63: USBメモリ他外部ストレージの運用の例外（役員・システム部・申請者用）の社内既定の作成。（加藤さん・磯辺さん確認中）
B64: ="No"&ROW()-3 -> No61 | C64: 課題 | D64: 伊藤 | E64: 45798 | F64: 0.41666667 | G64: 0.43055556 | H64: 0.013888889 | I64: 45798 | J64: 45798 | K64: 総務関連 | O64: 低 | P64: 完了 | Q64: LANケーブル、マウスなどのシステムに関わる備品のForestway での購入。 | R64: 既定手順で対応済
B65: ="No"&ROW()-3 -> No62 | C65: 要望 | D65: 坂本 | E65: 45799 | F65: 0.43402778 | G65: 0.44444444 | H65: 0.010416667 | I65: 45799 | J65: 45799 | K65: 業務運用 | L65: 顧客部 | N65: 池田 | O65: 中 | P65: 完了 | Q65: 在庫引き当て | R65: 既定手順で対応済
...

Sheet 祝日シート
A1: 45517
A2: 45518
A3: 45519
A4: 45656
A5: 45657
A6: 45658
A7: 45659
A8: 45660
A9: 45882
A10: 45883
A11: 45884
A12: 46021
... A24: 46390
