Workbook

Sheet Sheet1
A1: カタチラ番号(em310) | B1: カタチラ名(em310) | C1: 品目cd(em310) | D1: 注文番号(em310) | E1: 更新除外(品目) | F1: 更新除外(注文番号) | G1: カタチラ品目名(em310) | H1: カタチラ品目名2(em311) | I1: 追加表示1 | J1: 追加表示2 | K1: 追加表示3 | L1: サイト表示品名 | M1: 商品名の頭に追加するKW | N1: マクロあと | O1: 商品名追加KW | P1: まとめ買いKW | Q1: 分類KW | R1: 足し算 | S1: メーカー名(em120_2) | T1: 販売荷姿cd(em310) | U1: 販売荷姿名(em170) | V1: カタチラ中分類cd(em311) | W1: カタチラ小分類cd(em311) | X1: カタチラ細分類cd(em311) | Y1: 品目大分類cd(em160) | Z1: 品目大分類名(em50) | AA1: 品目中分類cd(em160) | AB1: 品目中分類名(em380) | AC1: 品目小分類cd(em163) | AD1: 品目小分類名(em381) | AE1: 品目細分類cd(em163) | AF1: 品目細分類名(em382) | AG1: 発売日YYMMDD(em163)
A2: 111 | B2: ココデカウ（楽天市場） | C2: J600AM | D2: R0251T | E2: =VLOOKUP(C2,[1]更新除外!$B:$F,5,0) -> #N/A | F2: =VLOOKUP(D2,[1]更新除外!$D:$F,3,0) -> #N/A | G2: 富士手袋/合皮手袋 ﾌﾞﾚﾘｽｽﾄﾛﾝｸﾞｷｬｯﾁ ﾌﾞﾙｰ迷彩 L | I2: 【お取り寄せ】 | L2: 【お取り寄せ】富士手袋 合皮手袋 ﾌﾞﾚﾘｽｽﾄﾛﾝｸﾞｷｬｯﾁ ﾌﾞﾙｰ迷彩 L | N2: 【お取り寄せ】富士手袋 合皮手袋 ブレリスストロングキャッチ ブルー迷彩 L | Q2: ポリウレタン手袋 革手袋 合皮手袋 ＰＵ手袋 作業用手袋 | R2: 【お取り寄せ】富士手袋 合皮手袋 ブレリスストロングキャッチ ブルー迷彩 L ポリウレタン手袋 革手袋 合皮手袋 ＰＵ手袋 作業用手袋 | S2: 富士手袋工業 | T2: 12 | U2: 双 | V2: 415 | W2: 41502 | X2: 101870 | Y2: 17 | Z2: 梱包・作業用品 | AA2: 1716 | AB2: 作業用手袋／軍足 | AC2: 171610 | AD2: 革手袋・合皮手袋・ＰＵ手袋 | AE2: 17161035 | AF2: ポリウレタン手袋 | AG2: 211224
A3: 111 | B3: ココデカウ（楽天市場） | C3: J682ER | D3: R9344U | E3: =VLOOKUP(C3,[1]更新除外!$B:$F,5,0) -> #N/A | F3: =VLOOKUP(D3,[1]更新除外!$D:$F,3,0) -> #N/A | G3: ﾌｰﾊﾞｰ ﾏｲｸﾛﾌｧｲﾊﾞｰｸﾞﾛｰﾌﾞ ｲﾝｻｲﾄﾞﾍﾞﾙﾄﾓﾃﾞﾙ 黒/ｷｬﾒﾙ L/ | I3: 【お取り寄せ】 | L3: 【お取り寄せ】ﾌｰﾊﾞｰ ﾏｲｸﾛﾌｧｲﾊﾞｰｸﾞﾛｰﾌﾞ ｲﾝｻｲﾄﾞﾍﾞﾙﾄﾓﾃﾞﾙ 黒 ｷｬﾒﾙ L | N3: 【お取り寄せ】フーバー マイクロファイバーグローブ インサイドベルトモデル 黒 キャメル L | Q3: ポリウレタン手袋 革手袋 合皮手袋 ＰＵ手袋 作業用手袋 | R3: 【お取り寄せ】フーバー マイクロファイバーグローブ インサイドベルトモデル 黒 キャメル L ポリウレタン手袋 革手袋 合皮手袋 ＰＵ手袋 作業用手袋 | S3: おたふく手袋 | T3: 12 | U3: 双 | V3: 415 | W3: 41502 | X3: 100691 | Y3: 17 | Z3: 梱包・作業用品 | AA3: 1716 | AB3: 作業用手袋／軍足 | AC3: 171610 | AD3: 革手袋・合皮手袋・ＰＵ手袋 | AE3: 17161035 | AF3: ポリウレタン手袋 | AG3: 211224
A4: 111 | B4: ココデカウ（楽天市場） | C4: J8836W | D4: R679KB | E4: =VLOOKUP(C4,[1]更新除外!$B:$F,5,0) -> #N/A | F4: =VLOOKUP(D4,[1]更新除外!$D:$F,3,0) -> #N/A | G4: ﾗｲｵﾝ事務器/電動ﾊﾟﾝﾁ 2穴式 穿孔500枚 DP-500S/20170 | H4: ﾗｲｵﾝ事務器/電動ﾊﾟﾝﾁ 2穴式 穿孔500枚 DP-500S/20170 | I4: 【メーカー直送】 | K4: 【代引不可】 | L4: 【メーカー直送】ﾗｲｵﾝ事務器 電動ﾊﾟﾝﾁ 2穴式 穿孔500枚 DP-500S 20170【代引不可】 | N4: 【メーカー直送】ライオン事務器 電動パンチ 2穴式 穿孔500枚 DP-500S 20170【代引不可】 | Q4: オートパワーパンチ 電動 パンチ 文具 事務 | R4: 【メーカー直送】ライオン事務器 電動パンチ 2穴式 穿孔500枚 DP-500S 20170【代引不可】 オートパワーパンチ 電動 パンチ 文具 事務 | S4: ライオン事務器 | T4: 12 | U4: 台 | V4: 401 | W4: 40109 | X4: 401712 | Y4: 6 | Z4: 文具・事務用品 | AA4: 605 | AB4: 切る、貼る、留める用品 | AC4: 60525 | AD4: パンチ | AE4: 6052515 | AF4: オートパワーパンチ（電動） | AG4: 241115
A5: 111 | B5: ココデカウ（楽天市場） | C5: 3622BA | D5: R087NV | E5: =VLOOKUP(C5,[1]更新除外!$B:$F,5,0) -> #N/A | F5: =VLOOKUP(D5,[1]更新除外!$D:$F,3,0) -> #N/A | G5: ｱｰﾙ･ｴﾌ･ﾔﾏｶﾜ/indice ﾌﾞｯｸｴﾝﾄﾞ 5色ｾｯﾄ/RFBS-JP | H5: ｱｰﾙ･ｴﾌ･ﾔﾏｶﾜ/indice ﾌﾞｯｸｴﾝﾄﾞ 5色ｾｯﾄ/RFBS-JP | I5: 【メーカー直送】 | K5: 【代引不可】 | L5: 【メーカー直送】ｱｰﾙ･ｴﾌ･ﾔﾏｶﾜ indice ﾌﾞｯｸｴﾝﾄﾞ 5色ｾｯﾄ RFBS-JP【代引不可】 | N5: 【メーカー直送】アール・エフ・ヤマカワ indice ブックエンド 5色セット RFBS-JP【代引不可】 | Q5: 本立て ブックスタンド デスクトップ収納 デスク周り 文具 | R5: 【メーカー直送】アール・エフ・ヤマカワ indice ブックエンド 5色セット RFBS-JP【代引不可】 本立て ブックスタンド デスクトップ収納 デスク周り 文具 | S5: アール・エフ・ヤマカワＳＨ | T5: 12 | U5: 台 | V5: 401 | W5: 40101 | X5: 301692 | Y5: 6 | Z5: 文具・事務用品 | AA5: 610 | AB5: デスク周り用品 | AC5: 61005 | AD5: デスクトップ収納 | AE5: 6100530 | AF5: 本立て／ブックスタンド | AG5: 260703
A6: 111 | B6: ココデカウ（楽天市場） | C6: J87484 | D6: RD5596 | E6: =VLOOKUP(C6,[1]更新除外!$B:$F,5,0) -> #N/A | F6: =VLOOKUP(D6,[1]更新除外!$D:$F,3,0) -> #N/A | G6: ﾌｼﾞﾃｯｸｽ/PET製仕切りﾎﾞｰﾄﾞ Mｻｲｽﾞ/1611204005 | I6: 【メーカー直送】 | K6: 【代引不可】【お客様組立】 | L6: 【メーカー直送】ﾌｼﾞﾃｯｸｽ PET製仕切りﾎﾞｰﾄﾞ Mｻｲｽﾞ 1611204005【代引不可】【お客様組立】 | N6: 【メーカー直送】フジテックス PET製仕切りボード Mサイズ 1611204005【代引不可】【お客様組立】 | Q6: デスク周り 文具 | R6: 【メーカー直送】フジテックス PET製仕切りボード Mサイズ 1611204005【代引不可】【お客様組立】 デスク周り 文具 | S6: フジテックス | T6: 12 | U6: ｾｯﾄ | V6: 401 | W6: 40101 | X6: 205749 | Y6: 6 | Z6: 文具・事務用品 | AA6: 610 | AB6: デスク周り用品 | AC6: 61090 | AD6: その他 | AE6: 6109005 | AF6: その他 | AG6: 200709
A7: 111 | B7: ココデカウ（楽天市場） | C7: J87485 | D7: RD5597 | E7: =VLOOKUP(C7,[1]更新除外!$B:$F,5,0) -> #N/A | F7: =VLOOKUP(D7,[1]更新除外!$D:$F,3,0) -> #N/A | G7: ﾌｼﾞﾃｯｸｽ/PET製仕切りﾎﾞｰﾄﾞ Sｻｲｽﾞ/1611204004 | I7: 【メーカー直送】 | K7: 【代引不可】【お客様組立】 | L7: 【メーカー直送】ﾌｼﾞﾃｯｸｽ PET製仕切りﾎﾞｰﾄﾞ Sｻｲｽﾞ 1611204004【代引不可】【お客様組立】 | N7: 【メーカー直送】フジテックス PET製仕切りボード Sサイズ 1611204004【代引不可】【お客様組立】 | Q7: デスク周り 文具 | R7: 【メーカー直送】フジテックス PET製仕切りボード Sサイズ 1611204004【代引不可】【お客様組立】 デスク周り 文具 | S7: フジテックス | T7: 12 | U7: ｾｯﾄ | V7: 401 | W7: 40101 | X7: 205749 | Y7: 6 | Z7: 文具・事務用品 | AA7: 610 | AB7: デスク周り用品 | AC7: 61090 | AD7: その他 | AE7: 6109005 | AF7: その他 | AG7: 200709
A8: 111 | B8: ココデカウ（楽天市場） | C8: J690PX | D8: R5112R | E8: =VLOOKUP(C8,[1]更新除外!$B:$F,5,0) -> #N/A | F8: =VLOOKUP(D8,[1]更新除外!$D:$F,3,0) -> #N/A | G8: ｺｸﾖ/ｵﾌｨｽﾗｳﾝｼﾞ ｴﾆｰｿﾌｧ 背なし ｵﾘｰﾌﾞｲｴﾛｰ | I8: 【メーカー直送】 | K8: 【代引不可】【組立・設置・送料無料】 | L8: 【メーカー直送】ｺｸﾖ ｵﾌｨｽﾗｳﾝｼﾞ ｴﾆｰｿﾌｧ 背なし ｵﾘｰﾌﾞｲｴﾛｰ【代引不可】【組立・設置・送料無料】 | N8: 【メーカー直送】コクヨ オフィスラウンジ エニーソファ 背なし オリーブイエロー【代引不可】【組立・設置・送料無料】 | Q8: キャスター脚 カフェ ラウンジチェア ミーティングチェア オフィス家具 | R8: 【メーカー直送】コクヨ オフィスラウンジ エニーソファ 背なし オリーブイエロー【代引不可】【組立・設置・送料無料】 キャスター脚 カフェ ラウンジチェア ミーティングチェア オフィス家具 | S8: コクヨ | T8: 12 | U8: 脚 | V8: 405 | W8: 40501 | X8: 205754 | Y8: 20 | Z8: オフィス家具 | AA8: 2013 | AB8: ミーティングチェア | AC8: 201350 | AD8: カフェ・ラウンジチェア | AE8: 20135010 | AF8: キャスター脚 | AG8: 230623
A9: 111 | B9: ココデカウ（楽天市場） | C9: J691PX | D9: R5113R | E9: =VLOOKUP(C9,[1]更新除外!$B:$F,5,0) -> #N/A | F9: =VLOOKUP(D9,[1]更新除外!$D:$F,3,0) -> #N/A | G9: ｺｸﾖ/ｵﾌｨｽﾗｳﾝｼﾞ ｴﾆｰｿﾌｧ 背なし ｱｯｼｭﾀｰｺｲｽﾞ | I9: 【メーカー直送】 | K9: 【代引不可】【組立・設置・送料無料】 | L9: 【メーカー直送】ｺｸﾖ ｵﾌｨｽﾗｳﾝｼﾞ ｴﾆｰｿﾌｧ 背なし ｱｯｼｭﾀｰｺｲｽﾞ【代引不可】【組立・設置・送料無料】 | N9: 【メーカー直送】コクヨ オフィスラウンジ エニーソファ 背なし アッシュターコイズ【代引不可】【組立・設置・送料無料】 | Q9: キャスター脚 カフェ ラウンジチェア ミーティングチェア オフィス家具 | R9: 【メーカー直送】コクヨ オフィスラウンジ エニーソファ 背なし アッシュターコイズ【代引不可】【組立・設置・送料無料】 キャスター脚 カフェ ラウンジチェア ミーティングチェア オフィス家具 | S9: コクヨ | T9: 12 | U9: 脚 | V9: 405 | W9: 40501 | X9: 205754 | Y9: 20 | Z9: オフィス家具 | AA9: 2013 | AB9: ミーティングチェア | AC9: 201350 | AD9: カフェ・ラウンジチェア | AE9: 20135010 | AF9: キャスター脚 | AG9: 230623
A10: 111 | B10: ココデカウ（楽天市場） | C10: 939204 | D10: R20238 | E10: =VLOOKUP(C10,[1]更新除外!$B:$F,5,0) -> #N/A | F10: =VLOOKUP(D10,[1]更新除外!$D:$F,3,0) -> #N/A | G10: 薬)本草製薬/ｾﾝﾅ錠-T ﾋﾟﾝｸ 220錠 | I10: 【お取り寄せ】 | J10: 【第(2)類医薬品】 | L10: 【お取り寄せ】【第(2)類医薬品】薬)本草製薬 ｾﾝﾅ錠-T ﾋﾟﾝｸ 220錠 | N10: 【お取り寄せ】【第(2)類医薬品】薬)本草製薬 センナ錠-T ピンク 220錠 | Q10: 錠剤 便秘薬 浣腸 医薬品 | R10: 【お取り寄せ】【第(2)類医薬品】薬)本草製薬 センナ錠-T ピンク 220錠 錠剤 便秘薬 浣腸 医薬品 | S10: 本草製薬 | T10: 12 | U10: 本 | V10: 131 | W10: 13105 | X10: 564520 | Y10: 40 | Z10: 医薬品 | AA10: 4025 | AB10: 便秘薬・浣腸 | AC10: 402505 | AD10: 便秘薬 | AE10: 40250505 | AF10: 錠剤 | AG10: 150121
A11: 111 | B11: ココデカウ（楽天市場） | C11: 938258 | D11: R19315 | E11: =VLOOKUP(C11,[1]更新除外!$B:$F,5,0) -> #N/A | F11: =VLOOKUP(D11,[1]更新除外!$D:$F,3,0) -> #N/A | G11: 薬)久光製薬/快腹丸 660錠(15錠X44包) | I11: 【お取り寄せ】 | J11: 【第(2)類医薬品】 | L11: 【お取り寄せ】【第(2)類医薬品】薬)久光製薬 快腹丸 660錠(15錠X44包) | N11: 【お取り寄せ】【第(2)類医薬品】薬)久光製薬 快腹丸 660錠(15錠X44包) | Q11: 錠剤 便秘薬 浣腸 医薬品 | R11: 【お取り寄せ】【第(2)類医薬品】薬)久光製薬 快腹丸 660錠(15錠X44包) 錠剤 便秘薬 浣腸 医薬品 | S11: 久光製薬 | T11: 12 | U11: 箱 | V11: 131 | W11: 13105 | X11: 564520 | Y11: 40 | Z11: 医薬品 | AA11: 4025 | AB11: 便秘薬・浣腸 | AC11: 402505 | AD11: 便秘薬 | AE11: 40250505 | AF11: 錠剤 | AG11: 150121
A12: 111 | B12: ココデカウ（楽天市場） | C12: 630845 | D12: R35373 | E12: =VLOOKUP(C12,[1]更新除外!$B:$F,5,0) -> #N/A | F12: =VLOOKUP(D12,[1]更新除外!$D:$F,3,0) -> #N/A | G12: ★薬)久光製薬/ｱﾚｸﾞﾗFX 14錠 | I12: 【お取り寄せ】 | J12: 【第2類医薬品】 | L12: 【お取り寄せ】【第2類医薬品】★薬)久光製薬 ｱﾚｸﾞﾗFX 14錠 | N12: 【お取り寄せ】【第2類医薬品】★薬)久光製薬 アレグラFX 14錠 | Q12: 錠剤 花粉 アレルギー 鼻炎 医薬品 | R12: 【お取り寄せ】【第2類医薬品】★薬)久光製薬 アレグラFX 14錠 錠剤 花粉 アレルギー 鼻炎 医薬品 | S12: 久光製薬 | T12: 12 | U12: 箱 | V12: 131 | W12: 13110 | X12: 558751 | Y12: 40 | Z12: 医薬品 | AA12: 4010 | AB12: 鼻炎・アレルギー | AC12: 401010 | AD12: 花粉・アレルギー | AE12: 40101005 | AF12: 錠剤 | AG12: 170228
A13: 111 | B13: ココデカウ（楽天市場） | C13: 188438 | D13: R19303 | E13: =VLOOKUP(C13,[1]更新除外!$B:$F,5,0) -> #N/A | F13: =VLOOKUP(D13,[1]更新除外!$D:$F,3,0) -> #N/A | G13: ★薬)ﾛｰﾄ製薬/ｱﾙｶﾞｰﾄﾞ ｸｲｯｸﾁｭｱﾌﾞﾙ 15錠 | I13: 【お取り寄せ】 | J13: 【第2類医薬品】 | L13: 【お取り寄せ】【第2類医薬品】★薬)ﾛｰﾄ製薬 ｱﾙｶﾞｰﾄﾞ ｸｲｯｸﾁｭｱﾌﾞﾙ 15錠 | N13: 【お取り寄せ】【第2類医薬品】★薬)ロート製薬 アルガード クイックチュアブル 15錠 | Q13: 花粉 アレルギー 鼻炎 医薬品 | R13: 【お取り寄せ】【第2類医薬品】★薬)ロート製薬 アルガード クイックチュアブル 15錠 花粉 アレルギー 鼻炎 医薬品 | S13: ロート製薬 | T13: 12 | U13: 箱 | V13: 131 | W13: 13110 | X13: 558751 | Y13: 40 | Z13: 医薬品 | AA13: 4010 | AB13: 鼻炎・アレルギー | AC13: 401010 | AD13: 花粉・アレルギー | AE13: 40101090 | AF13: その他 | AG13: 160517
A14: 111 | B14: ココデカウ（楽天市場） | C14: 939171 | D14: R20206 | E14: =VLOOKUP(C14,[1]更新除外!$B:$F,5,0) -> #N/A | F14: =VLOOKUP(D14,[1]更新除外!$D:$F,3,0) -> #N/A | G14: 薬)共立薬品工業/ﾎﾟﾋﾟｸﾙX ｸｰﾙ&ｸｰﾙ 30ml | I14: 【お取り寄せ】 | J14: 【第3類医薬品】 | L14: 【お取り寄せ】【第3類医薬品】薬)共立薬品工業 ﾎﾟﾋﾟｸﾙX ｸｰﾙ&ｸｰﾙ 30ml | N14: 【お取り寄せ】【第3類医薬品】薬)共立薬品工業 ポピクルX クール&クール 30ml | Q14: スプレー のどの荒れ 炎症 せき のど うがい薬 医薬品 | R14: 【お取り寄せ】【第3類医薬品】薬)共立薬品工業 ポピクルX クール&クール 30ml スプレー のどの荒れ 炎症 せき のど うがい薬 医薬品 | S14: 共立薬品工業 | T14: 12 | U14: 本 | V14: 131 | W14: 13115 | X14: 553371 | Y14: 40 | Z14: 医薬品 | AA14: 4015 | AB14: せき・のど・うがい薬 | AC14: 401510 | AD14: のどの荒れ・炎症 | AE14: 40151025 | AF14: スプレー | AG14: 150121
A15: 111 | B15: ココデカウ（楽天市場） | C15: 938468 | D15: R19519 | E15: =VLOOKUP(C15,[1]更新除外!$B:$F,5,0) -> #N/A | F15: =VLOOKUP(D15,[1]更新除外!$D:$F,3,0) -> #N/A | G15: 薬)小林製薬/のどぬｰるｽﾌﾟﾚｰｷｯｽﾞC 15ml | I15: 【お取り寄せ】 | J15: 【第3類医薬品】 | L15: 【お取り寄せ】【第3類医薬品】薬)小林製薬 のどぬｰるｽﾌﾟﾚｰｷｯｽﾞC 15ml | N15: 【お取り寄せ】【第3類医薬品】薬)小林製薬 のどぬーるスプレーキッズC 15ml | Q15: スプレー のどの荒れ 炎症 せき のど うがい薬 医薬品 | R15: 【お取り寄せ】【第3類医薬品】薬)小林製薬 のどぬーるスプレーキッズC 15ml スプレー のどの荒れ 炎症 せき のど うがい薬 医薬品 | S15: 小林製薬 | T15: 12 | U15: 本 | V15: 131 | W15: 13115 | X15: 553371 | Y15: 40 | Z15: 医薬品 | AA15: 4015 | AB15: せき・のど・うがい薬 | AC15: 401510 | AD15: のどの荒れ・炎症 | AE15: 40151025 | AF15: スプレー | AG15: 150121
A16: 111 | B16: ココデカウ（楽天市場） | C16: 210654 | D16: 701826 | E16: =VLOOKUP(C16,[1]更新除外!$B:$F,5,0) -> 外部委託商品 | F16: =VLOOKUP(D16,[1]更新除外!$D:$F,3,0) -> 外部委託商品 | G16: 【法人限定】高白色 ｺﾋﾟｰ用紙 EX A4 5000枚 500枚×10 | H16: 【法人限定】高白色 ｺﾋﾟｰ用紙 EX A4 5000枚 500枚×10冊 Forestway | L16: 【法人限定】高白色 ｺﾋﾟｰ用紙 EX A4 5000枚 500枚×10冊 Forestway | M16: 【16時までの注文で翌日お届け】 | N16: 【法人限定】高白色 コピー用紙 EX A4 5000枚 500枚×10冊 Forestway | O16: コピー紙 印刷用紙 オフィス用品 大量印刷 事務用品 書類 FAX 両面 資料 印刷 実用品 備品 白コピー用紙 高品質 | P16: まとめ買い 業務用 箱売り 箱買い ケース買い | Q16: Ａ４サイズ コピー用紙 | R16: 【16時までの注文で翌日お届け】 【法人限定】高白色 コピー用紙 EX A4 5000枚 500枚×10冊 Forestway コピー紙 印刷用紙 オフィス用品 大量印刷 事務用品 書類 FAX 両面 資料 印刷 実用品 備品 白コピー用紙 高品質 まとめ買い 業務用 箱売り 箱買い ケース買い Ａ４サイズ コピー用紙 | S16: ﾌｫｰﾚｽﾄｵﾘｼﾞﾅﾙ | T16: 12 | U16: 箱 | V16: 401 | W16: 40104 | X16: 303145 | Y16: 1 | Z16: コピー用紙・ＯＡ用紙 | AA16: 105 | AB16: コピー用紙 | AC16: 10505 | AD16: Ａ４サイズ | AE16: 1050505 | AF16: 5000枚 | AG16: 241221
A17: 111 | B17: ココデカウ（楽天市場） | C17: 624959 | D17: 766492 | E17: =VLOOKUP(C17,[1]更新除外!$B:$F,5,0) -> #N/A | F17: =VLOOKUP(D17,[1]更新除外!$D:$F,3,0) -> #N/A | G17: 春日製紙/ｺｱ･ﾕｰｽ 無包装170m 48ﾛｰﾙ/K-S170 | L17: 春日製紙 ｺｱ･ﾕｰｽ 無包装170m 48ﾛｰﾙ K-S170 | M17: トイレットペーパー | N17: 春日製紙 コア・ユース 無包装170m 48ロール K-S170 | O17: 48巻 シングル 芯なし 1箱 箱買い 大容量 まとめ買い 業務用 買い置き ストック コアユース 長尺 なかなか減らない ゴミが出ない 巻きが長い 交換が少ない 省スペース 長く使える 長持ち 包装なし | Q17: 業務用パック トイレットペーパー | R17: トイレットペーパー 春日製紙 コア・ユース 無包装170m 48ロール K-S170 48巻 シングル 芯なし 1箱 箱買い 大容量 まとめ買い 業務用 買い置き ストック コアユース 長尺 なかなか減らない ゴミが出ない 巻きが長い 交換が少ない 省スペース 長く使える 長持ち 包装なし 業務用パック トイレットペーパー | S17: 春日製紙 | T17: 12 | U17: 箱 | V17: 403 | W17: 40301 | X17: 501098 | Y17: 13 | Z17: 日用品・防災用品 | AA17: 1305 | AB17: 紙製品 | AC17: 130520 | AD17: トイレットペーパー | AE17: 13052005 | AF17: 業務用パック | AG17: 850101
A18: 111 | B18: ココデカウ（楽天市場） | C18: 507591 | D18: R47948 | E18: =VLOOKUP(C18,[1]更新除外!$B:$F,5,0) -> #N/A | F18: =VLOOKUP(D18,[1]更新除外!$D:$F,3,0) -> sku対応 | G18: ﾌｧｰｽﾄﾚｲﾄ/ﾚｷﾞｭﾗｰｺｯﾌﾟ 7ｵﾝｽ 無地 1000個/FR-278 | H18: ﾌｧｰｽﾄﾚｲﾄ/ﾚｷﾞｭﾗｰｺｯﾌﾟ 7ｵﾝｽ 無地 1000個/FR-278 | L18: ﾌｧｰｽﾄﾚｲﾄ ﾚｷﾞｭﾗｰｺｯﾌﾟ 7ｵﾝｽ 無地 1000個 FR-278 | M18: 紙コップ | N18: ファーストレイト レギュラーコップ 7オンス 無地 1000個 FR-278 | O18: 使い捨て コップ 業務用 まとめ買い 大量買い 箱買い アウトドア レジャー BBQ 試飲 休憩 休憩室 休憩所 病院 法人 備品 アメニティ | Q18: 無地 紙コップ 使いきり食器 キッチン テーブル | R18: 紙コップ ファーストレイト レギュラーコップ 7オンス 無地 1000個 FR-278 使い捨て コップ 業務用 まとめ買い 大量買い 箱買い アウトドア レジャー BBQ 試飲 休憩 休憩室 休憩所 病院 法人 備品 アメニティ 無地 紙コップ 使いきり食器 キッチン テーブル | S18: ファーストレイト | T18: 12 | U18: 箱 | V18: 403 | W18: 40309 | X18: 215980 | Y18: 14 | Z18: キッチン・テーブル用品 | AA18: 1420 | AB18: 使いきり食器 | AC18: 142010 | AD18: 紙コップ | AE18: 14201005 | AF18: 無地 | AG18: 190122
A19: 111 | B19: ココデカウ（楽天市場） | C19: JW9838 | D19: RK4915 | E19: =VLOOKUP(C19,[1]更新除外!$B:$F,5,0) -> #N/A | F19: =VLOOKUP(D19,[1]更新除外!$D:$F,3,0) -> #N/A | G19: ｷﾝｸﾞｼﾞﾑ/ｽﾀｯｸﾊﾞｽｹｯﾄ ﾍﾞｰｼﾞｭ 15個/KSP002S-BE | I19: 【お取り寄せ】 | L19: 【お取り寄せ】ｷﾝｸﾞｼﾞﾑ ｽﾀｯｸﾊﾞｽｹｯﾄ ﾍﾞｰｼﾞｭ 15個 KSP002S-BE | N19: 【お取り寄せ】キングジム スタックバスケット ベージュ 15個 KSP002S-BE | P19: まとめ買い 箱買い 買いだめ 買い置き 業務用 | Q19: 収納家具 インテリア 収納 | R19: 【お取り寄せ】キングジム スタックバスケット ベージュ 15個 KSP002S-BE まとめ買い 箱買い 買いだめ 買い置き 業務用 収納家具 インテリア 収納 | S19: キングジム | T19: 12 | U19: 箱 | V19: 405 | W19: 40504 | X19: 406605 | Y19: 21 | Z19: インテリア・寝具・収納 | AA19: 2105 | AB19: 収納家具 | AC19: 210590 | AD19: その他収納 | AE19: 21059005 | AF19: その他収納 | AG19: 210902
A20: 111 | B20: ココデカウ（楽天市場） | C20: 171245 | D20: R4845E | E20: =VLOOKUP(C20,[1]更新除外!$B:$F,5,0) -> #N/A | F20: =VLOOKUP(D20,[1]更新除外!$D:$F,3,0) -> #N/A | G20: ｼｽﾃﾑﾎﾟﾘﾏｰ/石灰石約25%を使用したｴｺﾎﾟﾘ袋 30L 50枚*30 | I20: 【お取り寄せ】 | L20: 【お取り寄せ】ｼｽﾃﾑﾎﾟﾘﾏｰ 石灰石約25%を使用したｴｺﾎﾟﾘ袋 30L 50枚*30 | N20: 【お取り寄せ】システムポリマー 石灰石約25%を使用したエコポリ袋 30L 50枚*30 | P20: まとめ買い 箱買い 買いだめ 買い置き 業務用 | Q20: 半透明タイプ ゴミ袋 ゴミ箱 清掃 | R20: 【お取り寄せ】システムポリマー 石灰石約25%を使用したエコポリ袋 30L 50枚*30 まとめ買い 箱買い 買いだめ 買い置き 業務用 半透明タイプ ゴミ袋 ゴミ箱 清掃 | S20: システムポリマー | T20: 12 | U20: 箱 | V20: 403 | W20: 40302 | X20: 216044 | Y20: 12 | Z20: 洗剤・清掃 | AA20: 1225 | AB20: ゴミ袋、ゴミ箱 | AC20: 122505 | AD20: ゴミ袋 | AE20: 12250505 | AF20: 半透明タイプ | AG20: 221222
A21: 111 | B21: ココデカウ（楽天市場） | C21: J19029 | D21: R65975 | E21: =VLOOKUP(C21,[1]更新除外!$B:$F,5,0) -> #N/A | F21: =VLOOKUP(D21,[1]更新除外!$D:$F,3,0) -> #N/A | G21: ﾄﾝﾎﾞ鉛筆/液体のり ｱｸｱﾋﾟｯﾄ 15本/HCA-311 | I21: 【お取り寄せ】 | L21: 【お取り寄せ】ﾄﾝﾎﾞ鉛筆 液体のり ｱｸｱﾋﾟｯﾄ 15本 HCA-311 | N21: 【お取り寄せ】トンボ鉛筆 液体のり アクアピット 15本 HCA-311 | O21: 工作のり 学校 | Q21: スティックのり のり 接着剤 切る 貼る 留める 文具 事務 | R21: 【お取り寄せ】トンボ鉛筆 液体のり アクアピット 15本 HCA-311 工作のり 学校 スティックのり のり 接着剤 切る 貼る 留める 文具 事務 | S21: トンボ鉛筆 | T21: 13 | U21: ｾｯﾄ | V21: 401 | W21: 40106 | X21: 301683 | Y21: 6 | Z21: 文具・事務用品 | AA21: 605 | AB21: 切る、貼る、留める用品 | AC21: 60510 | AD21: のり／接着剤 | AE21: 6051005 | AF21: スティックのり | AG21: 191022
A22: 111 | B22: ココデカウ（楽天市場） | C22: J16439 | D22: R63101 | E22: =VLOOKUP(C22,[1]更新除外!$B:$F,5,0) -> #N/A | F22: =VLOOKUP(D22,[1]更新除外!$D:$F,3,0) -> #N/A | G22: ｺｸﾖ/ｽﾃｨｯｸのり 四角 しっかり貼る S 20個/ﾀ-G301N-1P | I22: 【お取り寄せ】 | L22: 【お取り寄せ】ｺｸﾖ ｽﾃｨｯｸのり 四角 しっかり貼る S 20個 ﾀ-G301N-1P | N22: 【お取り寄せ】コクヨ スティックのり 四角 しっかり貼る S 20個 タ-G301N-1P | O22: かわいい おしゃれ 幼稚園 小学校 保育園 業務用 まとめ買い 大容量 工作のり 学校 | Q22: スティックのり のり 接着剤 切る 貼る 留める 文具 事務 | R22: 【お取り寄せ】コクヨ スティックのり 四角 しっかり貼る S 20個 タ-G301N-1P かわいい おしゃれ 幼稚園 小学校 保育園 業務用 まとめ買い 大容量 工作のり 学校 スティックのり のり 接着剤 切る 貼る 留める 文具 事務 | S22: コクヨ | T22: 13 | U22: 包 | V22: 401 | W22: 40106 | X22: 301683 | Y22: 6 | Z22: 文具・事務用品 | AA22: 605 | AB22: 切る、貼る、留める用品 | AC22: 60510 | AD22: のり／接着剤 | AE22: 6051005 | AF22: スティックのり | AG22: 190722
A23: 111 | B23: ココデカウ（楽天市場） | C23: 603602 | D23: 753891 | E23: =VLOOKUP(C23,[1]更新除外!$B:$F,5,0) -> #N/A | F23: =VLOOKUP(D23,[1]更新除外!$D:$F,3,0) -> sku対応 | G23: ｸﾗﾌﾄ封筒 角6 85g／ｍ2 100枚/K85-K6 | H23: ｸﾗﾌﾄ封筒 角6 85g／ｍ2 100枚/K85-K6 | L23: ｸﾗﾌﾄ封筒 角6 85g／ｍ2 100枚 K85-K6 | N23: クラフト封筒 角6 85g／ｍ2 100枚 K85-K6 | O23: 角6封筒 | Q23: 角６ Ａ５判用 角タイプ封筒 ノート | R23: クラフト封筒 角6 85g／ｍ2 100枚 K85-K6 角6封筒 角６ Ａ５判用 角タイプ封筒 ノート | S23: ツバメ工業 | T23: 12 | U23: ﾊﾟｯｸ | V23: 401 | W23: 40110 | X23: 301621 | Y23: 4 | Z23: ノート・紙製品 | AA23: 430 | AB23: 封筒 | AC23: 43005 | AD23: 角タイプ封筒 | AE23: 4300535 | AF23: 角６（Ａ５判用） | AG23: 850101
A24: 111 | B24: ココデカウ（楽天市場） | C24: 603604 | D24: 753892 | E24: =VLOOKUP(C24,[1]更新除外!$B:$F,5,0) -> 外部委託商品 | F24: =VLOOKUP(D24,[1]更新除外!$D:$F,3,0) -> sku対応 | G24: ｸﾗﾌﾄ封筒 角6 85g／ｍ2 1000枚/K85-K6 | L24: ｸﾗﾌﾄ封筒 角6 85g／ｍ2 1000枚 K85-K6 | N24: クラフト封筒 角6 85g／ｍ2 1000枚 K85-K6 | O24: 角6封筒 A5封筒 郵便番号枠なし | P24: まとめ買い 箱買い 買いだめ 買い置き 業務用 | Q24: 角６ Ａ５判用 角タイプ封筒 ノート | R24: クラフト封筒 角6 85g／ｍ2 1000枚 K85-K6 角6封筒 A5封筒 郵便番号枠なし まとめ買い 箱買い 買いだめ 買い置き 業務用 角６ Ａ５判用 角タイプ封筒 ノート | S24: ツバメ工業 | T24: 12 | U24: 箱 | V24: 401 | W24: 40110 | X24: 301621 | Y24: 4 | Z24: ノート・紙製品 | AA24: 430 | AB24: 封筒 | AC24: 43005 | AD24: 角タイプ封筒 | AE24: 4300535 | AF24: 角６（Ａ５判用） | AG24: 850101
A25: 111 | B25: ココデカウ（楽天市場） | C25: 603598 | D25: 753888 | E25: =VLOOKUP(C25,[1]更新除外!$B:$F,5,0) -> #N/A | F25: =VLOOKUP(D25,[1]更新除外!$D:$F,3,0) -> sku対応 | G25: ｸﾗﾌﾄ封筒 角4 85g／ｍ2 500枚/K85-K4 | L25: ｸﾗﾌﾄ封筒 角4 85g／ｍ2 500枚 K85-K4 | N25: クラフト封筒 角4 85g／ｍ2 500枚 K85-K4 | O25: B5封筒 テープ無し 郵便番号枠なし | Q25: 角４ Ｂ５判用 角タイプ封筒 ノート | R25: クラフト封筒 角4 85g／ｍ2 500枚 K85-K4 B5封筒 テープ無し 郵便番号枠なし 角４ Ｂ５判用 角タイプ封筒 ノート | S25: ツバメ工業 | T25: 13 | U25: 箱 | V25: 401 | W25: 40110 | X25: 301621 | Y25: 4 | Z25: ノート・紙製品 | AA25: 430 | AB25: 封筒 | AC25: 43005 | AD25: 角タイプ封筒 | AE25: 4300525 | AF25: 角４（Ｂ５判用） | AG25: 850101
A26: 111 | B26: ココデカウ（楽天市場） | C26: 603598 | D26: 753887 | E26: =VLOOKUP(C26,[1]更新除外!$B:$F,5,0) -> #N/A | F26: =VLOOKUP(D26,[1]更新除外!$D:$F,3,0) -> sku対応 | G26: ｸﾗﾌﾄ封筒 角4 85g／ｍ2 100枚/K85-K4 | L26: ｸﾗﾌﾄ封筒 角4 85g／ｍ2 100枚 K85-K4 | N26: クラフト封筒 角4 85g／ｍ2 100枚 K85-K4 | O26: B5封筒 テープ無し 郵便番号枠なし | Q26: 角４ Ｂ５判用 角タイプ封筒 ノート | R26: クラフト封筒 角4 85g／ｍ2 100枚 K85-K4 B5封筒 テープ無し 郵便番号枠なし 角４ Ｂ５判用 角タイプ封筒 ノート | S26: ツバメ工業 | T26: 12 | U26: ﾊﾟｯｸ | V26: 401 | W26: 40110 | X26: 301621 | Y26: 4 | Z26: ノート・紙製品 | AA26: 430 | AB26: 封筒 | AC26: 43005 | AD26: 角タイプ封筒 | AE26: 4300525 | AF26: 角４（Ｂ５判用） | AG26: 850101
A27: 111 | B27: ココデカウ（楽天市場） | C27: 603596 | D27: 753886 | E27: =VLOOKUP(C27,[1]更新除外!$B:$F,5,0) -> #N/A | F27: =VLOOKUP(D27,[1]更新除外!$D:$F,3,0) -> sku対応 | G27: ｸﾗﾌﾄ封筒 角3 85g／ｍ2 500枚/K85-K3 | L27: ｸﾗﾌﾄ封筒 角3 85g／ｍ2 500枚 K85-K3 | N27: クラフト封筒 角3 85g／ｍ2 500枚 K85-K3 | O27: B5封筒 郵便番号枠なし | P27: まとめ買い 箱買い 買いだめ 買い置き 業務用 | Q27: 角３ Ｂ５判 書籍雑誌用 角タイプ封筒 ノート | R27: クラフト封筒 角3 85g／ｍ2 500枚 K85-K3 B5封筒 郵便番号枠なし まとめ買い 箱買い 買いだめ 買い置き 業務用 角３ Ｂ５判 書籍雑誌用 角タイプ封筒 ノート | S27: ツバメ工業 | T27: 13 | U27: 箱 | V27: 401 | W27: 40110 | X27: 301621 | Y27: 4 | Z27: ノート・紙製品 | AA27: 430 | AB27: 封筒 | AC27: 43005 | AD27: 角タイプ封筒 | AE27: 4300520 | AF27: 角３（Ｂ５判・書籍雑誌用） | AG27: 850101
A28: 111 | B28: ココデカウ（楽天市場） | C28: 626678 | D28: 767568 | E28: =VLOOKUP(C28,[1]更新除外!$B:$F,5,0) -> #N/A | F28: =VLOOKUP(D28,[1]更新除外!$D:$F,3,0) -> sku対応 | G28: ｾﾞﾌﾞﾗ/ﾏｯｷｰｹｱ 極細 詰替ﾀｲﾌﾟ ﾋﾟﾝｸ/YYTS5-P | H28: ｾﾞﾌﾞﾗ/ﾏｯｷｰｹｱ 極細 詰替ﾀｲﾌﾟ ﾋﾟﾝｸ/YYTS5-P | L28: ｾﾞﾌﾞﾗ ﾏｯｷｰｹｱ 極細 詰替ﾀｲﾌﾟ ﾋﾟﾝｸ YYTS5-P | N28: ゼブラ マッキーケア 極細 詰替タイプ ピンク YYTS5-P | Q28: マッキー ゼブラ 油性ペン 油性マーカー | R28: ゼブラ マッキーケア 極細 詰替タイプ ピンク YYTS5-P マッキー ゼブラ 油性ペン 油性マーカー | S28: ｾﾞﾌﾞﾗ | T28: 12 | U28: 本 | V28: 401 | W28: 40103 | X28: 567257 | Y28: 5 | Z28: 筆記用具 | AA28: 535 | AB28: 油性ペン／油性マーカー | AC28: 53505 | AD28: マッキー（ゼブラ） | AE28: 5350590 | AF28: その他の色 | AG28: 850101
A29: 111 | B29: ココデカウ（楽天市場） | C29: 626680 | D29: 767569 | E29: =VLOOKUP(C29,[1]更新除外!$B:$F,5,0) -> #N/A | F29: =VLOOKUP(D29,[1]更新除外!$D:$F,3,0) -> sku対応 | G29: ｾﾞﾌﾞﾗ/ﾏｯｷｰｹｱ 極細 詰替ﾀｲﾌﾟ 紫/YYTS5-PU | H29: ｾﾞﾌﾞﾗ/ﾏｯｷｰｹｱ 極細 詰替ﾀｲﾌﾟ 紫/YYTS5-PU | L29: ｾﾞﾌﾞﾗ ﾏｯｷｰｹｱ 極細 詰替ﾀｲﾌﾟ 紫 YYTS5-PU | N29: ゼブラ マッキーケア 極細 詰替タイプ 紫 YYTS5-PU | Q29: マッキー ゼブラ 油性ペン 油性マーカー | R29: ゼブラ マッキーケア 極細 詰替タイプ 紫 YYTS5-PU マッキー ゼブラ 油性ペン 油性マーカー | S29: ｾﾞﾌﾞﾗ | T29: 12 | U29: 本 | V29: 401 | W29: 40103 | X29: 567257 | Y29: 5 | Z29: 筆記用具 | AA29: 535 | AB29: 油性ペン／油性マーカー | AC29: 53505 | AD29: マッキー（ゼブラ） | AE29: 5350590 | AF29: その他の色 | AG29: 850101
A30: 111 | B30: ココデカウ（楽天市場） | C30: 626676 | D30: 767567 | E30: =VLOOKUP(C30,[1]更新除外!$B:$F,5,0) -> #N/A | F30: =VLOOKUP(D30,[1]更新除外!$D:$F,3,0) -> sku対応 | G30: ｾﾞﾌﾞﾗ/ﾏｯｷｰｹｱ 極細 詰替ﾀｲﾌﾟ 緑/YYTS5-G | H30: ｾﾞﾌﾞﾗ/ﾏｯｷｰｹｱ 極細 詰替ﾀｲﾌﾟ 緑/YYTS5-G | L30: ｾﾞﾌﾞﾗ ﾏｯｷｰｹｱ 極細 詰替ﾀｲﾌﾟ 緑 YYTS5-G | N30: ゼブラ マッキーケア 極細 詰替タイプ 緑 YYTS5-G | Q30: マッキー ゼブラ 油性ペン 油性マーカー | R30: ゼブラ マッキーケア 極細 詰替タイプ 緑 YYTS5-G マッキー ゼブラ 油性ペン 油性マーカー | S30: ｾﾞﾌﾞﾗ | T30: 12 | U30: 本 | V30: 401 | W30: 40103 | X30: 567257 | Y30: 5 | Z30: 筆記用具 | AA30: 535 | AB30: 油性ペン／油性マーカー | AC30: 53505 | AD30: マッキー（ゼブラ） | AE30: 5350590 | AF30: その他の色 | AG30: 850101
A31: 111 | B31: ココデカウ（楽天市場） | C31: 612726 | D31: 770003 | E31: =VLOOKUP(C31,[1]更新除外!$B:$F,5,0) -> #N/A | F31: =VLOOKUP(D31,[1]更新除外!$D:$F,3,0) -> sku対応 | G31: ｾﾞﾌﾞﾗ/ﾏｯｷｰｹｱ 極細 詰替ﾀｲﾌﾟ 青 10本/YYTS5-BL | H31: ｾﾞﾌﾞﾗ/ﾏｯｷｰｹｱ 極細 詰替ﾀｲﾌﾟ 青 10本/YYTS5-BL | L31: ｾﾞﾌﾞﾗ ﾏｯｷｰｹｱ 極細 詰替ﾀｲﾌﾟ 青 10本 YYTS5-BL | N31: ゼブラ マッキーケア 極細 詰替タイプ 青 10本 YYTS5-BL | Q31: 青 ブルー系 マッキー ゼブラ 油性ペン 油性マーカー | R31: ゼブラ マッキーケア 極細 詰替タイプ 青 10本 YYTS5-BL 青 ブルー系 マッキー ゼブラ 油性ペン 油性マーカー | S31: ｾﾞﾌﾞﾗ | T31: 13 | U31: 箱 | V31: 401 | W31: 40103 | X31: 567257 | Y31: 5 | Z31: 筆記用具 | AA31: 535 | AB31: 油性ペン／油性マーカー | AC31: 53505 | AD31: マッキー（ゼブラ） | AE31: 5350514 | AF31: 青（ブルー系） | AG31: 850101
A32: 111 | B32: ココデカウ（楽天市場） | C32: 612726 | D32: 762261 | E32: =VLOOKUP(C32,[1]更新除外!$B:$F,5,0) -> #N/A | F32: =VLOOKUP(D32,[1]更新除外!$D:$F,3,0) -> sku対応 | G32: ｾﾞﾌﾞﾗ/ﾏｯｷｰｹｱ 極細 詰替ﾀｲﾌﾟ 青/YYTS5-BL | H32: ｾﾞﾌﾞﾗ/ﾏｯｷｰｹｱ 極細 詰替ﾀｲﾌﾟ 青/YYTS5-BL | L32: ｾﾞﾌﾞﾗ ﾏｯｷｰｹｱ 極細 詰替ﾀｲﾌﾟ 青 YYTS5-BL | N32: ゼブラ マッキーケア 極細 詰替タイプ 青 YYTS5-BL | Q32: 青 ブルー系 マッキー ゼブラ 油性ペン 油性マーカー | R32: ゼブラ マッキーケア 極細 詰替タイプ 青 YYTS5-BL 青 ブルー系 マッキー ゼブラ 油性ペン 油性マーカー | S32: ｾﾞﾌﾞﾗ | T32: 12 | U32: 本 | V32: 401 | W32: 40103 | X32: 567257 | Y32: 5 | Z32: 筆記用具 | AA32: 535 | AB32: 油性ペン／油性マーカー | AC32: 53505 | AD32: マッキー（ゼブラ） | AE32: 5350514 | AF32: 青（ブルー系） | AG32: 850101
A33: 111 | B33: ココデカウ（楽天市場） | C33: 626681 | D33: 767570 | E33: =VLOOKUP(C33,[1]更新除外!$B:$F,5,0) -> #N/A | F33: =VLOOKUP(D33,[1]更新除外!$D:$F,3,0) -> sku対応 | G33: ｾﾞﾌﾞﾗ/ﾏｯｷｰｹｱ 極細 詰替ﾀｲﾌﾟ 茶/YYTS5-E | H33: ｾﾞﾌﾞﾗ/ﾏｯｷｰｹｱ 極細 詰替ﾀｲﾌﾟ 茶/YYTS5-E | L33: ｾﾞﾌﾞﾗ ﾏｯｷｰｹｱ 極細 詰替ﾀｲﾌﾟ 茶 YYTS5-E | N33: ゼブラ マッキーケア 極細 詰替タイプ 茶 YYTS5-E | Q33: 茶色 ブラウン系 マッキー ゼブラ 油性ペン 油性マーカー | R33: ゼブラ マッキーケア 極細 詰替タイプ 茶 YYTS5-E 茶色 ブラウン系 マッキー ゼブラ 油性ペン 油性マーカー | S33: ｾﾞﾌﾞﾗ | T33: 12 | U33: 本 | V33: 401 | W33: 40103 | X33: 567257 | Y33: 5 | Z33: 筆記用具 | AA33: 535 | AB33: 油性ペン／油性マーカー | AC33: 53505 | AD33: マッキー（ゼブラ） | AE33: 5350530 | AF33: 茶色（ブラウン系） | AG33: 850101
A34: 111 | B34: ココデカウ（楽天市場） | C34: 612725 | D34: 768488 | E34: =VLOOKUP(C34,[1]更新除外!$B:$F,5,0) -> #N/A | F34: =VLOOKUP(D34,[1]更新除外!$D:$F,3,0) -> sku対応 | G34: ｾﾞﾌﾞﾗ/ﾏｯｷｰｹｱ 極細 詰替ﾀｲﾌﾟ 赤 10本/YYTS5-R | H34: ｾﾞﾌﾞﾗ/ﾏｯｷｰｹｱ 極細 詰替ﾀｲﾌﾟ 赤 10本/YYTS5-R | L34: ｾﾞﾌﾞﾗ ﾏｯｷｰｹｱ 極細 詰替ﾀｲﾌﾟ 赤 10本 YYTS5-R | N34: ゼブラ マッキーケア 極細 詰替タイプ 赤 10本 YYTS5-R | Q34: 赤 レッド系 マッキー ゼブラ 油性ペン 油性マーカー | R34: ゼブラ マッキーケア 極細 詰替タイプ 赤 10本 YYTS5-R 赤 レッド系 マッキー ゼブラ 油性ペン 油性マーカー | S34: ｾﾞﾌﾞﾗ | T34: 13 | U34: 箱 | V34: 401 | W34: 40103 | X34: 567257 | Y34: 5 | Z34: 筆記用具 | AA34: 535 | AB34: 油性ペン／油性マーカー | AC34: 53505 | AD34: マッキー（ゼブラ） | AE34: 5350509 | AF34: 赤（レッド系） | AG34: 850101
A35: 111 | B35: ココデカウ（楽天市場） | C35: 612725 | D35: 762260 | E35: =VLOOKUP(C35,[1]更新除外!$B:$F,5,0) -> #N/A | F35: =VLOOKUP(D35,[1]更新除外!$D:$F,3,0) -> sku対応 | G35: ｾﾞﾌﾞﾗ/ﾏｯｷｰｹｱ 極細 詰替ﾀｲﾌﾟ 赤/YYTS5-R | H35: ｾﾞﾌﾞﾗ/ﾏｯｷｰｹｱ 極細 詰替ﾀｲﾌﾟ 赤/YYTS5-R | L35: ｾﾞﾌﾞﾗ ﾏｯｷｰｹｱ 極細 詰替ﾀｲﾌﾟ 赤 YYTS5-R | N35: ゼブラ マッキーケア 極細 詰替タイプ 赤 YYTS5-R | Q35: 赤 レッド系 マッキー ゼブラ 油性ペン 油性マーカー | R35: ゼブラ マッキーケア 極細 詰替タイプ 赤 YYTS5-R 赤 レッド系 マッキー ゼブラ 油性ペン 油性マーカー | S35: ｾﾞﾌﾞﾗ | T35: 12 | U35: 本 | V35: 401 | W35: 40103 | X35: 567257 | Y35: 5 | Z35: 筆記用具 | AA35: 535 | AB35: 油性ペン／油性マーカー | AC35: 53505 | AD35: マッキー（ゼブラ） | AE35: 5350509 | AF35: 赤（レッド系） | AG35: 850101
A36: 111 | B36: ココデカウ（楽天市場） | C36: 612724 | D36: 754114 | E36: =VLOOKUP(C36,[1]更新除外!$B:$F,5,0) -> #N/A | F36: =VLOOKUP(D36,[1]更新除外!$D:$F,3,0) -> sku対応 | G36: ｾﾞﾌﾞﾗ/ﾏｯｷｰｹｱ 極細 詰替ﾀｲﾌﾟ 黒/YYTS5-BK | H36: ｾﾞﾌﾞﾗ/ﾏｯｷｰｹｱ 極細 詰替ﾀｲﾌﾟ 黒/YYTS5-BK | L36: ｾﾞﾌﾞﾗ ﾏｯｷｰｹｱ 極細 詰替ﾀｲﾌﾟ 黒 YYTS5-BK | N36: ゼブラ マッキーケア 極細 詰替タイプ 黒 YYTS5-BK | Q36: 黒 ブラック系 マッキー ゼブラ 油性ペン 油性マーカー | R36: ゼブラ マッキーケア 極細 詰替タイプ 黒 YYTS5-BK 黒 ブラック系 マッキー ゼブラ 油性ペン 油性マーカー | S36: ｾﾞﾌﾞﾗ | T36: 12 | U36: 本 | V36: 401 | W36: 40103 | X36: 567257 | Y36: 5 | Z36: 筆記用具 | AA36: 535 | AB36: 油性ペン／油性マーカー | AC36: 53505 | AD36: マッキー（ゼブラ） | AE36: 5350504 | AF36: 黒（ブラック系） | AG36: 850101
A37: 111 | B37: ココデカウ（楽天市場） | C37: 612724 | D37: 750947 | E37: =VLOOKUP(C37,[1]更新除外!$B:$F,5,0) -> #N/A | F37: =VLOOKUP(D37,[1]更新除外!$D:$F,3,0) -> sku対応 | G37: ｾﾞﾌﾞﾗ/ﾏｯｷｰｹｱ 極細 詰替ﾀｲﾌﾟ 黒 10本/YYTS5-BK | H37: ｾﾞﾌﾞﾗ/ﾏｯｷｰｹｱ 極細 詰替ﾀｲﾌﾟ 黒 10本/YYTS5-BK | L37: ｾﾞﾌﾞﾗ ﾏｯｷｰｹｱ 極細 詰替ﾀｲﾌﾟ 黒 10本 YYTS5-BK | N37: ゼブラ マッキーケア 極細 詰替タイプ 黒 10本 YYTS5-BK | Q37: 黒 ブラック系 マッキー ゼブラ 油性ペン 油性マーカー | R37: ゼブラ マッキーケア 極細 詰替タイプ 黒 10本 YYTS5-BK 黒 ブラック系 マッキー ゼブラ 油性ペン 油性マーカー | S37: ｾﾞﾌﾞﾗ | T37: 13 | U37: 箱 | V37: 401 | W37: 40103 | X37: 567257 | Y37: 5 | Z37: 筆記用具 | AA37: 535 | AB37: 油性ペン／油性マーカー | AC37: 53505 | AD37: マッキー（ゼブラ） | AE37: 5350504 | AF37: 黒（ブラック系） | AG37: 850101
A38: 111 | B38: ココデカウ（楽天市場） | C38: J710LY | D38: R6905B | E38: =VLOOKUP(C38,[1]更新除外!$B:$F,5,0) -> 外部委託商品 | F38: =VLOOKUP(D38,[1]更新除外!$D:$F,3,0) -> 外部委託商品 | G38: ｱｲﾘｽｵｰﾔﾏ/ｺﾝﾋﾞﾈｰｼｮﾝｻｰｸﾙ 93×65×122 ｳｫｰﾙﾅｯﾄ | I38: 【メーカー直送】 | K38: 【代引不可】【お客様組立】 | L38: 【メーカー直送】ｱｲﾘｽｵｰﾔﾏ ｺﾝﾋﾞﾈｰｼｮﾝｻｰｸﾙ 93×65×122 ｳｫｰﾙﾅｯﾄ【代引不可】【お客様組立】 | N38: 【メーカー直送】アイリスオーヤマ コンビネーションサークル 93×65×122 ウォールナット【代引不可】【お客様組立】 | O38: 猫用ケージ2段 | Q38: サークル 犬 ドッグ用 ペット お散歩 生活グッズ ペットハウス | R38: 【メーカー直送】アイリスオーヤマ コンビネーションサークル 93×65×122 ウォールナット【代引不可】【お客様組立】 猫用ケージ2段 サークル 犬 ドッグ用 ペット お散歩 生活グッズ ペットハウス | S38: ｱｲﾘｽｵｰﾔﾏ | T38: 12 | U38: 台 | V38: 409 | W38: 40906 | X38: 206193 | Y38: 22 | Z38: ペット・ガーデニング | AA38: 2230 | AB38: ペット用品／お散歩・生活グッズ・ペットハウス | AC38: 223005 | AD38: 犬（ドッグ）用 | AE38: 22300505 | AF38: サークル | AG38: 220723
A39: 111 | B39: ココデカウ（楽天市場） | C39: 120631 | D39: R14132 | E39: =VLOOKUP(C39,[1]更新除外!$B:$F,5,0) -> 外部委託商品 | F39: =VLOOKUP(D39,[1]更新除外!$D:$F,3,0) -> 外部委託商品 | G39: ｿﾆｯｸ/暗証番号ｷｰﾎﾞｯｸｽ ﾃﾝｷｰ式 24個吊/KS-7121 | L39: ｿﾆｯｸ 暗証番号ｷｰﾎﾞｯｸｽ ﾃﾝｷｰ式 24個吊 KS-7121 | N39: ソニック 暗証番号キーボックス テンキー式 24個吊 KS-7121 | O39: テンキー 暗証番号 暗証番号鍵 鍵入れボックス 鍵保管庫 | Q39: キーボックス キーホルダー 名札 | R39: ソニック 暗証番号キーボックス テンキー式 24個吊 KS-7121 テンキー 暗証番号 暗証番号鍵 鍵入れボックス 鍵保管庫 キーボックス キーホルダー 名札 | S39: ソニック | T39: 12 | U39: 台 | V39: 403 | W39: 40307 | X39: 567528 | Y39: 6 | Z39: 文具・事務用品 | AA39: 615 | AB39: 名札、キーホルダー | AC39: 61510 | AD39: キーホルダー、キーボックス | AE39: 6151015 | AF39: キーボックス | AG39: 150721
A40: 111 | B40: ココデカウ（楽天市場） | C40: 210656 | D40: 705572 | E40: =VLOOKUP(C40,[1]更新除外!$B:$F,5,0) -> 外部委託商品 | F40: =VLOOKUP(D40,[1]更新除外!$D:$F,3,0) -> 外部委託商品 | G40: 【法人限定】高白色 ｺﾋﾟｰ用紙 EX A4 2500枚 500枚×5 | H40: 【法人限定】高白色 ｺﾋﾟｰ用紙 EX A4 2500枚 500枚×5冊 Forestway | L40: 【法人限定】高白色 ｺﾋﾟｰ用紙 EX A4 2500枚 500枚×5冊 Forestway | N40: 【法人限定】高白色 コピー用紙 EX A4 2500枚 500枚×5冊 Forestway | O40: コピー紙 印刷用紙 オフィス用品 大量印刷 事務用品 書類 FAX 両面 資料 印刷 実用品 備品 白コピー用紙 高品質 | P40: まとめ買い 業務用 箱売り 箱買い ケース買い | R40: 【法人限定】高白色 コピー用紙 EX A4 2500枚 500枚×5冊 Forestway コピー紙 印刷用紙 オフィス用品 大量印刷 事務用品 書類 FAX 両面 資料 印刷 実用品 備品 白コピー用紙 高品質 まとめ買い 業務用 箱売り 箱買い ケース買い | S40: ﾌｫｰﾚｽﾄｵﾘｼﾞﾅﾙ | T40: 12 | U40: 箱 | V40: 401 | W40: 40104 | X40: 303145 | Y40: 1 | Z40: コピー用紙・ＯＡ用紙 | AA40: 105 | AB40: コピー用紙 | AC40: 10505 | AD40: Ａ４サイズ | AE40: 1050510 | AF40: 2500枚 | AG40: 241221
...
